Workbook
Name UPDATE: 'Data Sheet'!$E$1

Sheet Profit & Loss
A1: ='Data Sheet'!B1 -> J B CHEMICALS & PHARMACEUTICALS LTD | H1: =UPDATE | M1: SCREENER.IN
A3: Narration | B3: ='Data Sheet'!B16 -> 42460 | C3: ='Data Sheet'!C16 -> 42825 | D3: ='Data Sheet'!D16 -> 43190 | E3: ='Data Sheet'!E16 -> 43555 | F3: ='Data Sheet'!F16 -> 43921 | G3: ='Data Sheet'!G16 -> 44286 | H3: ='Data Sheet'!H16 -> 44651 | I3: ='Data Sheet'!I16 -> 45016 | ... K3: ='Data Sheet'!K16 -> 45747 | L3: Trailing | M3: Best Case | N3: Worst Case
A4: Sales | B4: ='Data Sheet'!B17 -> 1210.36 | C4: ='Data Sheet'!C17 -> 1344.29 | D4: ='Data Sheet'!D17 -> 1408.38 | E4: ='Data Sheet'!E17 -> 1643.2 | F4: ='Data Sheet'!F17 -> 1774.73 | G4: ='Data Sheet'!G17 -> 2042.52 | H4: ='Data Sheet'!H17 -> 2424.24 | I4: ='Data Sheet'!I17 -> 3149.28 | ... K4: ='Data Sheet'!K17 -> 3917.99 | L4: =SUM(#REF!) -> #REF! | M4: =$K4+M23*K4 -> 4597.8969 | N4: =$K4+N23*L4 -> #REF!
A5: Expenses | B5: =SUM('Data Sheet'!B18,'Data Sheet'!B20:B24, -1*'Data Sheet'!B19) -> 1004.29 | C5: =SUM('Data Sheet'!C18,'Data Sheet'!C20:C24, -1*'Data Sheet'!C19) -> 1111.91 | D5: =SUM('Data Sheet'!D18,'Data Sheet'!D20:D24, -1*'Data Sheet'!D19) -> 1190.83 | E5: =SUM('Data Sheet'!E18,'Data Sheet'!E20:E24, -1*'Data Sheet'!E19) -> 1337.36 | F5: =SUM('Data Sheet'!F18,'Data Sheet'!F20:F24, -1*'Data Sheet'!F19) -> 1397.16 | G5: =SUM('Data Sheet'!G18,'Data Sheet'!G20:G24, -1*'Data Sheet'!G19) -> 1482.11 | H5: =SUM('Data Sheet'!H18,'Data Sheet'!H20:H24, -1*'Data Sheet'!H19) -> 1880.79 | I5: =SUM('Data Sheet'!I18,'Data Sheet'!I20:I24, -1*'Data Sheet'!I19) -> 2453.53 | ... K5: =SUM('Data Sheet'!K18,'Data Sheet'!K20:K24, -1*'Data Sheet'!K19) -> 2886.15 | L5: =SUM(#REF!) -> #REF! | M5: =M4-M6 -> #REF! | N5: =N4-N6 -> #REF!
A6: Operating Profit | B6: =B4-B5 -> 206.07 | C6: =C4-C5 -> 232.38 | D6: =D4-D5 -> 217.55 | E6: =E4-E5 -> 305.84 | F6: =F4-F5 -> 377.57 | G6: =G4-G5 -> 560.41 | H6: =H4-H5 -> 543.45 | I6: =I4-I5 -> 695.75 | ... K6: =K4-K5 -> 1031.84 | L6: =SUM(#REF!) -> #REF! | M6: =M4*M24 -> #REF! | N6: =N4*N24 -> #REF!
A7: Other Income | B7: ='Data Sheet'!B25 -> 58.03 | C7: ='Data Sheet'!C25 -> 50.16 | D7: ='Data Sheet'!D25 -> 36.86 | E7: ='Data Sheet'!E25 -> 41.44 | F7: ='Data Sheet'!F25 -> 40.67 | G7: ='Data Sheet'!G25 -> 112.38 | H7: ='Data Sheet'!H25 -> 39.23 | I7: ='Data Sheet'!I25 -> 9.94 | ... K7: ='Data Sheet'!K25 -> 38.32 | L7: =SUM(#REF!) -> #REF! | M7: 0 | N7: 0
A8: Depreciation | B8: ='Data Sheet'!B26 -> 41.22 | C8: ='Data Sheet'!C26 -> 47.22 | D8: ='Data Sheet'!D26 -> 56.97 | E8: ='Data Sheet'!E26 -> 55.64 | F8: ='Data Sheet'!F26 -> 66.32 | G8: ='Data Sheet'!G26 -> 68.67 | H8: ='Data Sheet'!H26 -> 72.66 | I8: ='Data Sheet'!I26 -> 114.41 | ... K8: ='Data Sheet'!K26 -> 171.04 | L8: =SUM(#REF!) -> #REF! | M8: =+$L8 -> #REF! | N8: =+$L8 -> #REF!
A9: Interest | B9: ='Data Sheet'!B27 -> 10.65 | C9: ='Data Sheet'!C27 -> 5.37 | D9: ='Data Sheet'!D27 -> 3.49 | E9: ='Data Sheet'!E27 -> 4.65 | F9: ='Data Sheet'!F27 -> 3.03 | G9: ='Data Sheet'!G27 -> 7.24 | H9: ='Data Sheet'!H27 -> 5.12 | I9: ='Data Sheet'!I27 -> 36.05 | ... K9: ='Data Sheet'!K27 -> 11.73 | L9: =SUM(#REF!) -> #REF! | M9: =+$L9 -> #REF! | N9: =+$L9 -> #REF!
A10: Profit before tax | B10: ='Data Sheet'!B28 -> 212.23 | C10: ='Data Sheet'!C28 -> 229.95 | D10: ='Data Sheet'!D28 -> 193.95 | E10: ='Data Sheet'!E28 -> 286.99 | F10: ='Data Sheet'!F28 -> 348.89 | G10: ='Data Sheet'!G28 -> 596.88 | H10: ='Data Sheet'!H28 -> 504.9 | I10: ='Data Sheet'!I28 -> 555.23 | ... K10: ='Data Sheet'!K28 -> 887.39 | L10: =SUM(#REF!) -> #REF! | M10: =M6+M7-SUM(M8:M9) -> #REF! | N10: =N6+N7-SUM(N8:N9) -> #REF!
A11: Tax | B11: ='Data Sheet'!B29 -> 49.58 | C11: ='Data Sheet'!C29 -> 45.54 | D11: ='Data Sheet'!D29 -> 55.23 | E11: ='Data Sheet'!E29 -> 93.02 | F11: ='Data Sheet'!F29 -> 76.5 | G11: ='Data Sheet'!G29 -> 148.36 | H11: ='Data Sheet'!H29 -> 118.86 | I11: ='Data Sheet'!I29 -> 145.23 | ... K11: ='Data Sheet'!K29 -> 227.8 | L11: =SUM(#REF!) -> #REF! | M11: =IF($L10>0,$L11/$L10,0) -> #REF! | N11: =IF($L10>0,$L11/$L10,0) -> #REF!
A12: Net profit | B12: ='Data Sheet'!B30 -> 162.55 | C12: ='Data Sheet'!C30 -> 184.06 | D12: ='Data Sheet'!D30 -> 138.34 | E12: ='Data Sheet'!E30 -> 193.47 | F12: ='Data Sheet'!F30 -> 272.05 | G12: ='Data Sheet'!G30 -> 447.96 | H12: ='Data Sheet'!H30 -> 385.36 | I12: ='Data Sheet'!I30 -> 409.84 | ... K12: ='Data Sheet'!K30 -> 659.58 | L12: =SUM(#REF!) -> #REF! | M12: =M10-M11*M10 -> #REF! | N12: =N10-N11*N10 -> #REF!
A13: EPS | B13: =IF('Data Sheet'!B93>0,B12/'Data Sheet'!B93,0) -> 9.584316 | C13: =IF('Data Sheet'!C93>0,C12/'Data Sheet'!C93,0) -> 10.852594 | D13: =IF('Data Sheet'!D93>0,D12/'Data Sheet'!D93,0) -> 8.2788749 | E13: =IF('Data Sheet'!E93>0,E12/'Data Sheet'!E93,0) -> 12.054206 | F13: =IF('Data Sheet'!F93>0,F12/'Data Sheet'!F93,0) -> 17.597025 | G13: =IF('Data Sheet'!G93>0,G12/'Data Sheet'!G93,0) -> 28.97542 | H13: =IF('Data Sheet'!H93>0,H12/'Data Sheet'!H93,0) -> 24.926261 | I13: =IF('Data Sheet'!I93>0,I12/'Data Sheet'!I93,0) -> 26.475452 | ... K13: =IF('Data Sheet'!K93>0,K12/'Data Sheet'!K93,0) -> 42.362235 | L13: =IF('Data Sheet'!$B6>0,'Profit & Loss'!L12/'Data Sheet'!$B6,0) -> #REF! | M13: =IF('Data Sheet'!$B6>0,'Profit & Loss'!M12/'Data Sheet'!$B6,0) -> #REF! | N13: =IF('Data Sheet'!$B6>0,'Profit & Loss'!N12/'Data Sheet'!$B6,0) -> #REF!
A14: Price to earning | B14: =IF(B15>0,B15/B13,"") -> 13.01397 | C14: =IF(C15>0,C15/C13,"") -> 15.94826 | D14: =IF(D15>0,D15/D13,"") -> 18.72839 | E14: =IF(E15>0,E15/E13,"") -> 15.032098 | F14: =IF(F15>0,F15/F13,"") -> 14.462672 | G14: =IF(G15>0,G15/G13,"") -> 21.664224 | H14: =IF(H15>0,H15/H13,"") -> 31.59118 | I14: =IF(I15>0,I15/I13,"") -> 37.324386 | ... K14: =IF(K15>0,K15/K13,"") -> 38.317147 | L14: =IF(L13>0,L15/L13,0) -> #REF! | M14: =M25 -> #REF! | N14: =N25 -> #REF!
A15: Price | B15: ='Data Sheet'!B90 -> 124.73 | C15: ='Data Sheet'!C90 -> 173.08 | D15: ='Data Sheet'!D90 -> 155.05 | E15: ='Data Sheet'!E90 -> 181.2 | F15: ='Data Sheet'!F90 -> 254.5 | G15: ='Data Sheet'!G90 -> 627.73 | H15: ='Data Sheet'!H90 -> 787.45 | I15: ='Data Sheet'!I90 -> 988.18 | ... K15: ='Data Sheet'!K90 -> 1623.2 | L15: ='Data Sheet'!B8 -> 1846 | M15: =M13*M14 -> #REF! | N15: =N13*N14 -> #REF!
A17: RATIOS:
A18: Dividend Payout | B18: =IF('Data Sheet'!B30>0, 'Data Sheet'!B31/'Data Sheet'!B30, 0) -> 0.26084282 | C18: =IF('Data Sheet'!C30>0, 'Data Sheet'!C31/'Data Sheet'!C30, 0) -> 0.046071933 | D18: =IF('Data Sheet'!D30>0, 'Data Sheet'!D31/'Data Sheet'!D30, 0) -> 0.12078936 | E18: =IF('Data Sheet'!E30>0, 'Data Sheet'!E31/'Data Sheet'!E30, 0) -> 0.20737065 | F18: =IF('Data Sheet'!F30>0, 'Data Sheet'!F31/'Data Sheet'!F30, 0) -> 0.31255284 | G18: =IF('Data Sheet'!G30>0, 'Data Sheet'!G31/'Data Sheet'!G30, 0) -> 0.28471292 | H18: =IF('Data Sheet'!H30>0, 'Data Sheet'!H31/'Data Sheet'!H30, 0) -> 0.33096326 | I18: =IF('Data Sheet'!I30>0, 'Data Sheet'!I31/'Data Sheet'!I30, 0) -> 0.33520398 | ... K18: =IF('Data Sheet'!K30>0, 'Data Sheet'!K31/'Data Sheet'!K30, 0) -> 0.36589951
A19: OPM | B19: =IF(B6>0,B6/B4,0) -> 0.17025513 | C19: =IF(C6>0,C6/C4,0) -> 0.17286449 | D19: =IF(D6>0,D6/D4,0) -> 0.15446825 | E19: =IF(E6>0,E6/E4,0) -> 0.18612463 | F19: =IF(F6>0,F6/F4,0) -> 0.21274785 | G19: =IF(G6>0,G6/G4,0) -> 0.27437185 | H19: =IF(H6>0,H6/H4,0) -> 0.22417335 | I19: =IF(I6>0,I6/I4,0) -> 0.22092351 | ... L19: =IF(L6>0,L6/L4,0) -> #REF!
G22: TRENDS: | H22: 10 YEARS | I22: 7 YEARS | J22: 5 YEARS | K22: 3 YEARS | L22: RECENT | M22: BEST | N22: WORST
G23: Sales Growth | H23: =IF(B4=0,"",POWER($K4/B4,1/9)-1) -> 0.13941831 | I23: =IF(D4=0,"",POWER($K4/D4,1/7)-1) -> 0.15738444 | J23: =IF(F4=0,"",POWER($K4/F4,1/5)-1) -> 0.17161846 | K23: =IF(H4=0,"",POWER($K4/H4, 1/3)-1) -> 0.17353461 | L23: =IF(ISERROR(MAX(IF(J4=0,"",(K4-J4)/J4),IF(K4=0,"",(L4-K4)/K4))),"",MAX(IF(J4=0,"",(K4-J4)/J4),IF(K4=0,"",(L4-K4)/K4))) | M23: =MAX(K23:L23) -> 0.17353461 | N23: =MIN(H23:L23) -> 0.13941831
G24: OPM | H24: =IF(SUM(B4:$K$4)=0,"",SUMPRODUCT(B19:$K$19,B4:$K$4)/SUM(B4:$K$4)) -> 0.22625794 | I24: =IF(SUM(E4:$K$4)=0,"",SUMPRODUCT(E19:$K$19,E4:$K$4)/SUM(E4:$K$4)) -> 0.23931203 | J24: =IF(SUM(G4:$K$4)=0,"",SUMPRODUCT(G19:$K$19,G4:$K$4)/SUM(G4:$K$4)) -> 0.2482706 | K24: =IF(SUM(I4:$K$4)=0, "", SUMPRODUCT(I19:$K$19,I4:$K$4)/SUM(I4:$K$4)) -> 0.24875444 | L24: =L19 -> #REF! | M24: =MAX(K24:L24) -> #REF! | N24: =MIN(H24:L24) -> #REF!
G25: Price to Earning | H25: =IF(ISERROR(AVERAGEIF(B14:$L14,">0")),"",AVERAGEIF(B14:$L14,">0")) -> 25.243198 | I25: =IF(ISERROR(AVERAGEIF(E14:$L14,">0")),"",AVERAGEIF(E14:$L14,">0")) -> 29.248766 | J25: =IF(ISERROR(AVERAGEIF(G14:$L14,">0")),"",AVERAGEIF(G14:$L14,">0")) -> 35.049318 | K25: =IF(ISERROR(AVERAGEIF(I14:$L14,">0")),"",AVERAGEIF(I14:$L14,">0")) -> 40.663728 | L25: =L14 -> #REF! | M25: =MAX(K25:L25) -> #REF! | N25: =MIN(H25:L25) -> #REF!

Sheet Financials>

Sheet Historicals>
B2: ="Historical Financial Statements - "&'Data Sheet'!B1 -> Historical Financial Statements - J B CHEMICALS & PHARMACEUTICALS LTD
B3: Years | C3: ='Data Sheet'!B16 -> 42460 | D3: ='Data Sheet'!C16 -> 42825 | E3: ='Data Sheet'!D16 -> 43190 | F3: ='Data Sheet'!E16 -> 43555 | G3: ='Data Sheet'!F16 -> 43921 | H3: ='Data Sheet'!G16 -> 44286 | I3: ='Data Sheet'!H16 -> 44651 | J3: ='Data Sheet'!I16 -> 45016 | ... L3: ='Data Sheet'!K16 -> 45747 | M3: LTM
A5: # | B5: Income Statement
B6: Sales | C6: =IFERROR('Data Sheet'!B17,0) -> 1210.36 | D6: =IFERROR('Data Sheet'!C17,0) -> 1344.29 | E6: =IFERROR('Data Sheet'!D17,0) -> 1408.38 | F6: =IFERROR('Data Sheet'!E17,0) -> 1643.2 | G6: =IFERROR('Data Sheet'!F17,0) -> 1774.73 | H6: =IFERROR('Data Sheet'!G17,0) -> 2042.52 | I6: =IFERROR('Data Sheet'!H17,0) -> 2424.24 | J6: =IFERROR('Data Sheet'!I17,0) -> 3149.28 | ... L6: =IFERROR('Data Sheet'!K17,0) -> 3917.99 | M6: =IFERROR(SUM('Data Sheet'!H42:K42),0) -> 4193.04
B7: Sales Growth | C7: - | D7: =IFERROR(D6/C6-1,0) -> 0.11065303 | E7: =IFERROR(E6/D6-1,0) -> 0.047675725 | F7: =IFERROR(F6/E6-1,0) -> 0.16673057 | G7: =IFERROR(G6/F6-1,0) -> 0.080045034 | H7: =IFERROR(H6/G6-1,0) -> 0.15089056 | I7: =IFERROR(I6/H6-1,0) -> 0.18688679 | J7: =IFERROR(J6/I6-1,0) -> 0.2990793 | K7: =IFERROR(K6/J6-1,0) -> 0.10634177 | ... M7: =IFERROR(M6/L6-1,0) -> 0.070201813
B9: COGS | C9: =IFERROR(SUM('Data Sheet'!B18,'Data Sheet'!B20:B22,-1*('Data Sheet'!B19)),0) -> 773.33 | D9: =IFERROR(SUM('Data Sheet'!C18,'Data Sheet'!C20:C22,-1*('Data Sheet'!C19)),0) -> 878.39 | E9: =IFERROR(SUM('Data Sheet'!D18,'Data Sheet'!D20:D22,-1*('Data Sheet'!D19)),0) -> 923.57 | F9: =IFERROR(SUM('Data Sheet'!E18,'Data Sheet'!E20:E22,-1*('Data Sheet'!E19)),0) -> 1030.95 | G9: =IFERROR(SUM('Data Sheet'!F18,'Data Sheet'!F20:F22,-1*('Data Sheet'!F19)),0) -> 1092.83 | H9: =IFERROR(SUM('Data Sheet'!G18,'Data Sheet'!G20:G22,-1*('Data Sheet'!G19)),0) -> 1190.73 | I9: =IFERROR(SUM('Data Sheet'!H18,'Data Sheet'!H20:H22,-1*('Data Sheet'!H19)),0) -> 1452.4 | J9: =IFERROR(SUM('Data Sheet'!I18,'Data Sheet'!I20:I22,-1*('Data Sheet'!I19)),0) -> 1911.63 | ... L9: =IFERROR(SUM('Data Sheet'!K18,'Data Sheet'!K20:K22,-1*('Data Sheet'!K19)),0) -> 2234.2 | M9: =IFERROR(SUM('Data Sheet'!H43:K43),0) -> 3060.31
B10: COGS % of Sales | C10: =IFERROR(C9/C6,0) -> 0.63892561 | D10: =IFERROR(D9/D6,0) -> 0.653423 | E10: =IFERROR(E9/E6,0) -> 0.65576762 | F10: =IFERROR(F9/F6,0) -> 0.62740385 | G10: =IFERROR(G9/G6,0) -> 0.61577254 | H10: =IFERROR(H9/H6,0) -> 0.58297104 | I10: =IFERROR(I9/I6,0) -> 0.5991156 | J10: =IFERROR(J9/J6,0) -> 0.60700541 | ... M10: =IFERROR(M9/M6,0) -> 0.72985471
B12: Gross Profit | C12: =IFERROR(C6-C9,0) -> 437.03 | D12: =IFERROR(D6-D9,0) -> 465.9 | E12: =IFERROR(E6-E9,0) -> 484.81 | F12: =IFERROR(F6-F9,0) -> 612.25 | G12: =IFERROR(G6-G9,0) -> 681.9 | H12: =IFERROR(H6-H9,0) -> 851.79 | I12: =IFERROR(I6-I9,0) -> 971.84 | J12: =IFERROR(J6-J9,0) -> 1237.65 | ... M12: =IFERROR(M6-M9,0) -> 1132.73
B13: Gross Margin | C13: =IFERROR(C12/C6,0) -> 0.36107439 | D13: =IFERROR(D12/D6,0) -> 0.346577 | E13: =IFERROR(E12/E6,0) -> 0.34423238 | F13: =IFERROR(F12/F6,0) -> 0.37259615 | G13: =IFERROR(G12/G6,0) -> 0.38422746 | H13: =IFERROR(H12/H6,0) -> 0.41702896 | I13: =IFERROR(I12/I6,0) -> 0.4008844 | J13: =IFERROR(J12/J6,0) -> 0.39299459 | ... M13: =IFERROR(M12/M6,0) -> 0.27014529
B15: Selling & general exp | C15: =IFERROR(SUM('Data Sheet'!B23:B24),0) -> 230.96 | D15: =IFERROR(SUM('Data Sheet'!C23:C24),0) -> 233.52 | E15: =IFERROR(SUM('Data Sheet'!D23:D24),0) -> 267.26 | F15: =IFERROR(SUM('Data Sheet'!E23:E24),0) -> 306.41 | G15: =IFERROR(SUM('Data Sheet'!F23:F24),0) -> 304.33 | H15: =IFERROR(SUM('Data Sheet'!G23:G24),0) -> 291.38 | I15: =IFERROR(SUM('Data Sheet'!H23:H24),0) -> 428.39 | J15: =IFERROR(SUM('Data Sheet'!I23:I24),0) -> 541.9 | ... L15: =IFERROR(SUM('Data Sheet'!K23:K24),0) -> 651.95
B16: S&G Exp % of Sale | C16: =IFERROR(C15/C6,0) -> 0.19081926 | D16: =IFERROR(D15/D6,0) -> 0.17371252 | E16: =IFERROR(E15/E6,0) -> 0.18976413 | F16: =IFERROR(F15/F6,0) -> 0.18647152 | G16: =IFERROR(G15/G6,0) -> 0.17147961 | H16: =IFERROR(H15/H6,0) -> 0.14265711 | I16: =IFERROR(I15/I6,0) -> 0.17671105 | J16: =IFERROR(J15/J6,0) -> 0.17207108 | ... M16: =IFERROR(M15/M6,0) -> 0
B18: Other Income | C18: =IFERROR('Data Sheet'!B25,0) -> 58.03 | D18: =IFERROR('Data Sheet'!C25,0) -> 50.16 | E18: =IFERROR('Data Sheet'!D25,0) -> 36.86 | F18: =IFERROR('Data Sheet'!E25,0) -> 41.44 | G18: =IFERROR('Data Sheet'!F25,0) -> 40.67 | H18: =IFERROR('Data Sheet'!G25,0) -> 112.38 | I18: =IFERROR('Data Sheet'!H25,0) -> 39.23 | J18: =IFERROR('Data Sheet'!I25,0) -> 9.94 | ... L18: =IFERROR('Data Sheet'!K25,0) -> 38.32 | M18: =IFERROR(SUM('Data Sheet'!H44:K44),0) -> 62.65
B20: EBITDA | C20: =IFERROR(SUM(C12,C18)-C15,0) -> 264.1 | D20: =IFERROR(SUM(D12,D18)-D15,0) -> 282.54 | E20: =IFERROR(SUM(E12,E18)-E15,0) -> 254.41 | F20: =IFERROR(SUM(F12,F18)-F15,0) -> 347.28 | G20: =IFERROR(SUM(G12,G18)-G15,0) -> 418.24 | H20: =IFERROR(SUM(H12,H18)-H15,0) -> 672.79 | I20: =IFERROR(SUM(I12,I18)-I15,0) -> 582.68 | J20: =IFERROR(SUM(J12,J18)-J15,0) -> 705.69 | ... M20: =IFERROR(SUM(M12,M18)-M15,0) -> 1195.38
B21: EBITDA % of Sale | C21: =IFERROR(C20/C6,0) -> 0.21819954 | D21: =IFERROR(D20/D6,0) -> 0.21017786 | E21: =IFERROR(E20/E6,0) -> 0.18064017 | F21: =IFERROR(F20/F6,0) -> 0.21134372 | G21: =IFERROR(G20/G6,0) -> 0.23566402 | H21: =IFERROR(H20/H6,0) -> 0.32939212 | I21: =IFERROR(I20/I6,0) -> 0.24035574 | J21: =IFERROR(J20/J6,0) -> 0.22407979 | ... M21: =IFERROR(M20/M6,0) -> 0.28508672
B23: Interest | C23: =IFERROR('Data Sheet'!B27,0) -> 10.65 | D23: =IFERROR('Data Sheet'!C27,0) -> 5.37 | E23: =IFERROR('Data Sheet'!D27,0) -> 3.49 | F23: =IFERROR('Data Sheet'!E27,0) -> 4.65 | G23: =IFERROR('Data Sheet'!F27,0) -> 3.03 | H23: =IFERROR('Data Sheet'!G27,0) -> 7.24 | I23: =IFERROR('Data Sheet'!H27,0) -> 5.12 | J23: =IFERROR('Data Sheet'!I27,0) -> 36.05 | ... L23: =IFERROR('Data Sheet'!K27,0) -> 11.73 | M23: =IFERROR(SUM('Data Sheet'!H46:K46),0) -> 5.79
B24: Interest % of Sale | C24: =IFERROR(C23/C6,0) -> 0.008799035 | D24: =IFERROR(D23/D6,0) -> 0.0039946738 | E24: =IFERROR(E23/E6,0) -> 0.0024780244 | F24: =IFERROR(F23/F6,0) -> 0.0028298442 | G24: =IFERROR(G23/G6,0) -> 0.001707302 | H24: =IFERROR(H23/H6,0) -> 0.0035446409 | I24: =IFERROR(I23/I6,0) -> 0.0021120021 | J24: =IFERROR(J23/J6,0) -> 0.011447061 | ... M24: =IFERROR(M23/M6,0) -> 0.0013808597
B26: Depreciation | C26: =IFERROR('Data Sheet'!B26,0) -> 41.22 | D26: =IFERROR('Data Sheet'!C26,0) -> 47.22 | E26: =IFERROR('Data Sheet'!D26,0) -> 56.97 | F26: =IFERROR('Data Sheet'!E26,0) -> 55.64 | G26: =IFERROR('Data Sheet'!F26,0) -> 66.32 | H26: =IFERROR('Data Sheet'!G26,0) -> 68.67 | I26: =IFERROR('Data Sheet'!H26,0) -> 72.66 | J26: =IFERROR('Data Sheet'!I26,0) -> 114.41 | ... L26: =IFERROR('Data Sheet'!K26,0) -> 171.04 | M26: =IFERROR(SUM('Data Sheet'!H45:K45),0) -> 178.93
B27: Depreciation % of Sale | C27: =IFERROR(C26/C6,0) -> 0.034055983 | D27: =IFERROR(D26/D6,0) -> 0.035126349 | E27: =IFERROR(E26/E6,0) -> 0.040450731 | F27: =IFERROR(F26/F6,0) -> 0.033860759 | G27: =IFERROR(G26/G6,0) -> 0.037369065 | H27: =IFERROR(H26/H6,0) -> 0.033620234 | I27: =IFERROR(I26/I6,0) -> 0.02997228 | J27: =IFERROR(J26/J6,0) -> 0.036328939 | ... M27: =IFERROR(M26/M6,0) -> 0.042673096
B29: Earnings before Tax | C29: =IFERROR(C20-SUM(C26,C23),0) -> 212.23 | D29: =IFERROR(D20-SUM(D26,D23),0) -> 229.95 | E29: =IFERROR(E20-SUM(E26,E23),0) -> 193.95 | F29: =IFERROR(F20-SUM(F26,F23),0) -> 286.99 | G29: =IFERROR(G20-SUM(G26,G23),0) -> 348.89 | H29: =IFERROR(H20-SUM(H26,H23),0) -> 596.88 | I29: =IFERROR(I20-SUM(I26,I23),0) -> 504.9 | J29: =IFERROR(J20-SUM(J26,J23),0) -> 555.23 | ... M29: =IFERROR(M20-SUM(M26,M23),0) -> 1010.66
B30: EBT % of sales | C30: =IFERROR(C29/C6,0) -> 0.17534453 | D30: =IFERROR(D29/D6,0) -> 0.17105684 | E30: =IFERROR(E29/E6,0) -> 0.13771141 | F30: =IFERROR(F29/F6,0) -> 0.17465312 | G30: =IFERROR(G29/G6,0) -> 0.19658765 | H30: =IFERROR(H29/H6,0) -> 0.29222725 | I30: =IFERROR(I29/I6,0) -> 0.20827146 | J30: =IFERROR(J29/J6,0) -> 0.17630379 | ... M30: =IFERROR(M29/M6,0) -> 0.24103276
B32: Tax | C32: =IFERROR('Data Sheet'!B29,0) -> 49.58 | D32: =IFERROR('Data Sheet'!C29,0) -> 45.54 | E32: =IFERROR('Data Sheet'!D29,0) -> 55.23 | F32: =IFERROR('Data Sheet'!E29,0) -> 93.02 | G32: =IFERROR('Data Sheet'!F29,0) -> 76.5 | H32: =IFERROR('Data Sheet'!G29,0) -> 148.36 | I32: =IFERROR('Data Sheet'!H29,0) -> 118.86 | J32: =IFERROR('Data Sheet'!I29,0) -> 145.23 | ... L32: =IFERROR('Data Sheet'!K29,0) -> 227.8 | M32: =IFERROR(SUM('Data Sheet'!H48:K48),0) -> 256.88
B33: Effective Tax Rate | C33: =IFERROR(C32/C29,0) -> 0.23361447 | D33: =IFERROR(D32/D29,0) -> 0.19804305 | E33: =IFERROR(E32/E29,0) -> 0.28476411 | F33: =IFERROR(F32/F29,0) -> 0.32412279 | G33: =IFERROR(G32/G29,0) -> 0.21926682 | H33: =IFERROR(H32/H29,0) -> 0.24855917 | I33: =IFERROR(I32/I29,0) -> 0.23541295 | J33: =IFERROR(J32/J29,0) -> 0.26156728 | ... M33: =IFERROR(M32/M29,0) -> 0.25417054
B35: Net Profit | C35: =IFERROR(C29-C32,0) -> 162.65 | D35: =IFERROR(D29-D32,0) -> 184.41 | E35: =IFERROR(E29-E32,0) -> 138.72 | F35: =IFERROR(F29-F32,0) -> 193.97 | G35: =IFERROR(G29-G32,0) -> 272.39 | H35: =IFERROR(H29-H32,0) -> 448.52 | I35: =IFERROR(I29-I32,0) -> 386.04 | J35: =IFERROR(J29-J32,0) -> 410 | ... M35: =IFERROR(M29-M32,0) -> 753.78
B36: Net Margins | C36: =IFERROR(C35/C6,0) -> 0.13438151 | D36: =IFERROR(D35/D6,0) -> 0.13718022 | E36: =IFERROR(E35/E6,0) -> 0.098496145 | F36: =IFERROR(F35/F6,0) -> 0.11804406 | G36: =IFERROR(G35/G6,0) -> 0.1534825 | H36: =IFERROR(H35/H6,0) -> 0.21959149 | I36: =IFERROR(I35/I6,0) -> 0.15924166 | J36: =IFERROR(J35/J6,0) -> 0.13018849 | ... M36: =IFERROR(M35/M6,0) -> 0.17976933
B38: No of Equity Shares | C38: =IFERROR('Data Sheet'!B93,0) -> 16.96 | D38: =IFERROR('Data Sheet'!C93,0) -> 16.96 | E38: =IFERROR('Data Sheet'!D93,0) -> 16.71 | F38: =IFERROR('Data Sheet'!E93,0) -> 16.05 | G38: =IFERROR('Data Sheet'!F93,0) -> 15.46 | H38: =IFERROR('Data Sheet'!G93,0) -> 15.46 | I38: =IFERROR('Data Sheet'!H93,0) -> 15.46 | J38: =IFERROR('Data Sheet'!I93,0) -> 15.48 | ... L38: =IFERROR('Data Sheet'!K93,0) -> 15.57 | M38: -
B40: EPS | C40: =IFERROR(C35/C38,0) -> 9.5902123 | D40: =IFERROR(D35/D38,0) -> 10.873231 | E40: =IFERROR(E35/E38,0) -> 8.3016158 | F40: =IFERROR(F35/F38,0) -> 12.085358 | G40: =IFERROR(G35/G38,0) -> 17.619017 | H40: =IFERROR(H35/H38,0) -> 29.011643 | I40: =IFERROR(I35/I38,0) -> 24.970246 | J40: =IFERROR(J35/J38,0) -> 26.485788 | ... M40: =IFERROR(M35/M38,0) -> 0
B41: EPS Growth % | D41: =IFERROR(D40/C40-1,0) -> 0.1337842 | E41: =IFERROR(E40/D40-1,0) -> -0.23650884 | F41: =IFERROR(F40/E40-1,0) -> 0.45578386 | G41: =IFERROR(G40/F40-1,0) -> 0.45788122 | H41: =IFERROR(H40/G40-1,0) -> 0.64660964 | I41: =IFERROR(I40/H40-1,0) -> -0.1393026 | J41: =IFERROR(J40/I40-1,0) -> 0.060693929 | K41: =IFERROR(K40/J40-1,0) -> 0.34440414 | L41: =IFERROR(L40/K40-1,0) -> 0.18971438 | M41: -
B43: Dividend per Share | C43: =IFERROR('Data Sheet'!B31/C38,0) -> 2.5 | D43: =IFERROR('Data Sheet'!C31/D38,0) -> 0.5 | E43: =IFERROR('Data Sheet'!D31/E38,0) -> 1 | F43: =IFERROR('Data Sheet'!E31/F38,0) -> 2.4996885 | G43: =IFERROR('Data Sheet'!F31/G38,0) -> 5.5 | H43: =IFERROR('Data Sheet'!G31/H38,0) -> 8.2496766 | I43: =IFERROR('Data Sheet'!H31/I38,0) -> 8.2496766 | J43: =IFERROR('Data Sheet'!I31/J38,0) -> 8.874677 | ... L43: =IFERROR('Data Sheet'!K31/L38,0) -> 15.500321
B44: Dividend payout ratio | C44: =IFERROR(C43/C40,0) -> 0.26068245 | D44: =IFERROR(D43/D40,0) -> 0.045984491 | E44: =IFERROR(E43/E40,0) -> 0.12045848 | F44: =IFERROR(F43/F40,0) -> 0.20683611 | G44: =IFERROR(G43/G40,0) -> 0.31216271 | H44: =IFERROR(H43/H40,0) -> 0.28435744 | I44: =IFERROR(I43/I40,0) -> 0.33038027 | J44: =IFERROR(J43/J40,0) -> 0.33507317 | ... M44: =IFERROR(M43/M40,0) -> 0
B46: Retained Earning | C46: =IFERROR(IF(C40>C43,1-C44,0),0) -> 0.73931755 | D46: =IFERROR(IF(D40>D43,1-D44,0),0) -> 0.95401551 | E46: =IFERROR(IF(E40>E43,1-E44,0),0) -> 0.87954152 | F46: =IFERROR(IF(F40>F43,1-F44,0),0) -> 0.79316389 | G46: =IFERROR(IF(G40>G43,1-G44,0),0) -> 0.68783729 | H46: =IFERROR(IF(H40>H43,1-H44,0),0) -> 0.71564256 | I46: =IFERROR(IF(I40>I43,1-I44,0),0) -> 0.66961973 | J46: =IFERROR(IF(J40>J43,1-J44,0),0) -> 0.66492683 | ... M46: =IFERROR(IF(M40>M43,1-M44,0),0) -> 0
A48: # | B48: Balance Sheet
B49: Equity Share Capital | C49: =IFERROR('Data Sheet'!B57,0) -> 16.96 | D49: =IFERROR('Data Sheet'!C57,0) -> 16.96 | E49: =IFERROR('Data Sheet'!D57,0) -> 16.71 | F49: =IFERROR('Data Sheet'!E57,0) -> 16.05 | G49: =IFERROR('Data Sheet'!F57,0) -> 15.46 | H49: =IFERROR('Data Sheet'!G57,0) -> 15.46 | I49: =IFERROR('Data Sheet'!H57,0) -> 15.46 | J49: =IFERROR('Data Sheet'!I57,0) -> 15.48 | ... L49: =IFERROR('Data Sheet'!K57,0) -> 15.57
B50: Reserves | C50: =IFERROR('Data Sheet'!B58,0) -> 1166.87 | D50: =IFERROR('Data Sheet'!C58,0) -> 1346.71 | E50: =IFERROR('Data Sheet'!D58,0) -> 1424.84 | F50: =IFERROR('Data Sheet'!E58,0) -> 1464.08 | G50: =IFERROR('Data Sheet'!F58,0) -> 1420.03 | H50: =IFERROR('Data Sheet'!G58,0) -> 1794.27 | I50: =IFERROR('Data Sheet'!H58,0) -> 2118.67 | J50: =IFERROR('Data Sheet'!I58,0) -> 2464.88 | ... L50: =IFERROR('Data Sheet'!K58,0) -> 3417.75
B51: Borrowings | C51: =IFERROR('Data Sheet'!B59,0) -> 193.42 | D51: =IFERROR('Data Sheet'!C59,0) -> 48.86 | E51: =IFERROR('Data Sheet'!D59,0) -> 29.29 | F51: =IFERROR('Data Sheet'!E59,0) -> 25.8 | G51: =IFERROR('Data Sheet'!F59,0) -> 29.49 | H51: =IFERROR('Data Sheet'!G59,0) -> 44.98 | I51: =IFERROR('Data Sheet'!H59,0) -> 54.56 | J51: =IFERROR('Data Sheet'!I59,0) -> 572.45 | ... L51: =IFERROR('Data Sheet'!K59,0) -> 27.89
B52: Other Liabilities | C52: =IFERROR('Data Sheet'!B60,0) -> 270.41 | D52: =IFERROR('Data Sheet'!C60,0) -> 261.51 | E52: =IFERROR('Data Sheet'!D60,0) -> 294.27 | F52: =IFERROR('Data Sheet'!E60,0) -> 286.02 | G52: =IFERROR('Data Sheet'!F60,0) -> 349 | H52: =IFERROR('Data Sheet'!G60,0) -> 376.46 | I52: =IFERROR('Data Sheet'!H60,0) -> 412.28 | J52: =IFERROR('Data Sheet'!I60,0) -> 494.55 | ... L52: =IFERROR('Data Sheet'!K60,0) -> 804.15
B53: Total Liabilities | C53: =IFERROR(SUM(C49:C52),0) -> 1647.66 | D53: =IFERROR(SUM(D49:D52),0) -> 1674.04 | E53: =IFERROR(SUM(E49:E52),0) -> 1765.11 | F53: =IFERROR(SUM(F49:F52),0) -> 1791.95 | G53: =IFERROR(SUM(G49:G52),0) -> 1813.98 | H53: =IFERROR(SUM(H49:H52),0) -> 2231.17 | I53: =IFERROR(SUM(I49:I52),0) -> 2600.97 | J53: =IFERROR(SUM(J49:J52),0) -> 3547.36 | ... L53: =IFERROR(SUM(L49:L52),0) -> 4265.36
B55: Fixed Asset Net Block | C55: =IFERROR('Data Sheet'!B62,0) -> 440.22 | D55: =IFERROR('Data Sheet'!C62,0) -> 679.44 | E55: =IFERROR('Data Sheet'!D62,0) -> 639.5 | F55: =IFERROR('Data Sheet'!E62,0) -> 620.93 | G55: =IFERROR('Data Sheet'!F62,0) -> 651.26 | H55: =IFERROR('Data Sheet'!G62,0) -> 633.65 | I55: =IFERROR('Data Sheet'!H62,0) -> 1276.99 | J55: =IFERROR('Data Sheet'!I62,0) -> 1901.01 | ... L55: =IFERROR('Data Sheet'!K62,0) -> 1968.19
B56: Capital Work in Progress | C56: =IFERROR('Data Sheet'!B63,0) -> 134.89 | D56: =IFERROR('Data Sheet'!C63,0) -> 3.76 | E56: =IFERROR('Data Sheet'!D63,0) -> 17.4 | F56: =IFERROR('Data Sheet'!E63,0) -> 15.09 | G56: =IFERROR('Data Sheet'!F63,0) -> 16.17 | H56: =IFERROR('Data Sheet'!G63,0) -> 25.57 | I56: =IFERROR('Data Sheet'!H63,0) -> 18.68 | J56: =IFERROR('Data Sheet'!I63,0) -> 55.15 | ... L56: =IFERROR('Data Sheet'!K63,0) -> 63.05
B57: Investments | C57: =IFERROR('Data Sheet'!B64,0) -> 478.7 | D57: =IFERROR('Data Sheet'!C64,0) -> 410.8 | E57: =IFERROR('Data Sheet'!D64,0) -> 433.72 | F57: =IFERROR('Data Sheet'!E64,0) -> 456.53 | G57: =IFERROR('Data Sheet'!F64,0) -> 403.27 | H57: =IFERROR('Data Sheet'!G64,0) -> 677.88 | I57: =IFERROR('Data Sheet'!H64,0) -> 12.72 | J57: =IFERROR('Data Sheet'!I64,0) -> 205.97 | ... L57: =IFERROR('Data Sheet'!K64,0) -> 345.09
B58: Other Assets | C58: =IFERROR('Data Sheet'!B65-SUM('Data Sheet'!B67:B69),0) -> 120.33 | D58: =IFERROR('Data Sheet'!C65-SUM('Data Sheet'!C67:C69),0) -> 100.51 | E58: =IFERROR('Data Sheet'!D65-SUM('Data Sheet'!D67:D69),0) -> 130.11 | F58: =IFERROR('Data Sheet'!E65-SUM('Data Sheet'!E67:E69),0) -> 110.62 | G58: =IFERROR('Data Sheet'!F65-SUM('Data Sheet'!F67:F69),0) -> 92.23 | H58: =IFERROR('Data Sheet'!G65-SUM('Data Sheet'!G67:G69),0) -> 126.75 | I58: =IFERROR('Data Sheet'!H65-SUM('Data Sheet'!H67:H69),0) -> 268.4 | J58: =IFERROR('Data Sheet'!I65-SUM('Data Sheet'!I67:I69),0) -> 300.14 | ... L58: =IFERROR('Data Sheet'!K65-SUM('Data Sheet'!K67:K69),0) -> 415.24
...

Sheet Ratio Analysis
B2: ="Ratio Analysis - "& 'Data Sheet'!B1 -> Ratio Analysis - J B CHEMICALS & PHARMACEUTICALS LTD
B3: Years | C3: ='Historicals>'!C3 -> 42460 | D3: ='Historicals>'!D3 -> 42825 | E3: ='Historicals>'!E3 -> 43190 | F3: ='Historicals>'!F3 -> 43555 | G3: ='Historicals>'!G3 -> 43921 | H3: ='Historicals>'!H3 -> 44286 | I3: ='Historicals>'!I3 -> 44651 | J3: ='Historicals>'!J3 -> 45016 | ... L3: ='Historicals>'!L3 -> 45747 | M3: Trend | N3: Mean | O3: Median
B5: Sales Growth | D5: =IFERROR('Historicals>'!D7,0) -> 0.11065303 | E5: =IFERROR('Historicals>'!E7,0) -> 0.047675725 | F5: =IFERROR('Historicals>'!F7,0) -> 0.16673057 | G5: =IFERROR('Historicals>'!G7,0) -> 0.080045034 | H5: =IFERROR('Historicals>'!H7,0) -> 0.15089056 | I5: =IFERROR('Historicals>'!I7,0) -> 0.18688679 | J5: =IFERROR('Historicals>'!J7,0) -> 0.2990793 | K5: =IFERROR('Historicals>'!K7,0) -> 0.10634177 | L5: =IFERROR('Historicals>'!L7,0) -> 0.12450849 | N5: =IFERROR(AVERAGE(D5:L5),0) -> 0.14142347 | O5: =IFERROR(MEDIAN(C5:L5),0) -> 0.12450849
B6: EBITA Growth | D6: =IFERROR('Historicals>'!D20/'Historicals>'!C20-1,0) -> 0.069822037 | E6: =IFERROR('Historicals>'!E20/'Historicals>'!D20-1,0) -> -0.099561124 | F6: =IFERROR('Historicals>'!F20/'Historicals>'!E20-1,0) -> 0.36504068 | G6: =IFERROR('Historicals>'!G20/'Historicals>'!F20-1,0) -> 0.2043308 | H6: =IFERROR('Historicals>'!H20/'Historicals>'!G20-1,0) -> 0.60862184 | I6: =IFERROR('Historicals>'!I20/'Historicals>'!H20-1,0) -> -0.13393481 | J6: =IFERROR('Historicals>'!J20/'Historicals>'!I20-1,0) -> 0.21111073 | K6: =IFERROR('Historicals>'!K20/'Historicals>'!J20-1,0) -> 0.32375406 | L6: =IFERROR('Historicals>'!L20/'Historicals>'!K20-1,0) -> 0.14558534 | N6: =IFERROR(AVERAGE(D6:L6),0) -> 0.18830773 | O6: =IFERROR(MEDIAN(C6:L6),0) -> 0.2043308
B7: EBT Growth | D7: =IFERROR('Historicals>'!D29/'Historicals>'!C29-1,0) -> 0.083494322 | E7: =IFERROR('Historicals>'!E29/'Historicals>'!D29-1,0) -> -0.15655577 | F7: =IFERROR('Historicals>'!F29/'Historicals>'!E29-1,0) -> 0.47971127 | G7: =IFERROR('Historicals>'!G29/'Historicals>'!F29-1,0) -> 0.21568696 | H7: =IFERROR('Historicals>'!H29/'Historicals>'!G29-1,0) -> 0.7107971 | I7: =IFERROR('Historicals>'!I29/'Historicals>'!H29-1,0) -> -0.15410133 | J7: =IFERROR('Historicals>'!J29/'Historicals>'!I29-1,0) -> 0.099683106 | K7: =IFERROR('Historicals>'!K29/'Historicals>'!J29-1,0) -> 0.35351116 | L7: =IFERROR('Historicals>'!L29/'Historicals>'!K29-1,0) -> 0.1808093 | N7: =IFERROR(AVERAGE(D7:L7),0) -> 0.20144846 | O7: =IFERROR(MEDIAN(C7:L7),0) -> 0.1808093
B8: Net Profit Growth | D8: =IFERROR('Historicals>'!D35/'Historicals>'!C35-1,0) -> 0.1337842 | E8: =IFERROR('Historicals>'!E35/'Historicals>'!D35-1,0) -> -0.24776314 | F8: =IFERROR('Historicals>'!F35/'Historicals>'!E35-1,0) -> 0.39828431 | G8: =IFERROR('Historicals>'!G35/'Historicals>'!F35-1,0) -> 0.40428932 | H8: =IFERROR('Historicals>'!H35/'Historicals>'!G35-1,0) -> 0.64660964 | I8: =IFERROR('Historicals>'!I35/'Historicals>'!H35-1,0) -> -0.1393026 | J8: =IFERROR('Historicals>'!J35/'Historicals>'!I35-1,0) -> 0.062066107 | K8: =IFERROR('Historicals>'!K35/'Historicals>'!J35-1,0) -> 0.34787805 | L8: =IFERROR('Historicals>'!L35/'Historicals>'!K35-1,0) -> 0.19354722 | N8: =IFERROR(AVERAGE(D8:L8),0) -> 0.19993257 | O8: =IFERROR(MEDIAN(C8:L8),0) -> 0.19354722
B9: Dividend Growth | D9: =IFERROR('Historicals>'!D43/'Historicals>'!C43-1,0) -> -0.8 | E9: =IFERROR('Historicals>'!E43/'Historicals>'!D43-1,0) -> 1 | F9: =IFERROR('Historicals>'!F43/'Historicals>'!E43-1,0) -> 1.4996885 | G9: =IFERROR('Historicals>'!G43/'Historicals>'!F43-1,0) -> 1.2002742 | H9: =IFERROR('Historicals>'!H43/'Historicals>'!G43-1,0) -> 0.4999412 | I9: =IFERROR('Historicals>'!I43/'Historicals>'!H43-1,0) -> 0 | J9: =IFERROR('Historicals>'!J43/'Historicals>'!I43-1,0) -> 0.075760596 | K9: =IFERROR('Historicals>'!K43/'Historicals>'!J43-1,0) -> 0.38033193 | L9: =IFERROR('Historicals>'!L43/'Historicals>'!K43-1,0) -> 0.26533234 | N9: =IFERROR(AVERAGE(D9:L9),0) -> 0.45792541 | O9: =IFERROR(MEDIAN(C9:L9),0) -> 0.38033193
B11: Gross Margin | C11: =IFERROR('Historicals>'!C13,0) -> 0.36107439 | D11: =IFERROR('Historicals>'!D13,0) -> 0.346577 | E11: =IFERROR('Historicals>'!E13,0) -> 0.34423238 | F11: =IFERROR('Historicals>'!F13,0) -> 0.37259615 | G11: =IFERROR('Historicals>'!G13,0) -> 0.38422746 | H11: =IFERROR('Historicals>'!H13,0) -> 0.41702896 | I11: =IFERROR('Historicals>'!I13,0) -> 0.4008844 | J11: =IFERROR('Historicals>'!J13,0) -> 0.39299459 | ... L11: =IFERROR('Historicals>'!L13,0) -> 0.42975863 | N11: =IFERROR(AVERAGE(C11:L11),0) -> 0.38768404 | O11: =IFERROR(MEDIAN(C11:L11),0) -> 0.38861102
B12: EBIDTA Margin | C12: =IFERROR('Historicals>'!C21,0) -> 0.21819954 | D12: =IFERROR('Historicals>'!D21,0) -> 0.21017786 | E12: =IFERROR('Historicals>'!E21,0) -> 0.18064017 | F12: =IFERROR('Historicals>'!F21,0) -> 0.21134372 | G12: =IFERROR('Historicals>'!G21,0) -> 0.23566402 | H12: =IFERROR('Historicals>'!H21,0) -> 0.32939212 | I12: =IFERROR('Historicals>'!I21,0) -> 0.24035574 | J12: =IFERROR('Historicals>'!J21,0) -> 0.22407979 | ... L12: =IFERROR('Historicals>'!L21,0) -> 0.27314005 | N12: =IFERROR(AVERAGE(C12:L12),0) -> 0.23911078 | O12: =IFERROR(MEDIAN(C12:L12),0) -> 0.2298719
B13: EBIT Margin | C13: =IFERROR(('Historicals>'!C20-'Historicals>'!C26)/'Historicals>'!C6,0) -> 0.18414356 | D13: =IFERROR(('Historicals>'!D20-'Historicals>'!D26)/'Historicals>'!D6,0) -> 0.17505151 | E13: =IFERROR(('Historicals>'!E20-'Historicals>'!E26)/'Historicals>'!E6,0) -> 0.14018944 | F13: =IFERROR(('Historicals>'!F20-'Historicals>'!F26)/'Historicals>'!F6,0) -> 0.17748296 | G13: =IFERROR(('Historicals>'!G20-'Historicals>'!G26)/'Historicals>'!G6,0) -> 0.19829495 | H13: =IFERROR(('Historicals>'!H20-'Historicals>'!H26)/'Historicals>'!H6,0) -> 0.29577189 | I13: =IFERROR(('Historicals>'!I20-'Historicals>'!I26)/'Historicals>'!I6,0) -> 0.21038346 | J13: =IFERROR(('Historicals>'!J20-'Historicals>'!J26)/'Historicals>'!J6,0) -> 0.18775085 | ... L13: =IFERROR(('Historicals>'!L20-'Historicals>'!L26)/'Historicals>'!L6,0) -> 0.22948502 | N13: =IFERROR(AVERAGE(C13:L13),0) -> 0.20269689 | O13: =IFERROR(MEDIAN(C13:L13),0) -> 0.1930229
B14: EBT Margin | C14: =IFERROR('Historicals>'!C30,0) -> 0.17534453 | D14: =IFERROR('Historicals>'!D30,0) -> 0.17105684 | E14: =IFERROR('Historicals>'!E30,0) -> 0.13771141 | F14: =IFERROR('Historicals>'!F30,0) -> 0.17465312 | G14: =IFERROR('Historicals>'!G30,0) -> 0.19658765 | H14: =IFERROR('Historicals>'!H30,0) -> 0.29222725 | I14: =IFERROR('Historicals>'!I30,0) -> 0.20827146 | J14: =IFERROR('Historicals>'!J30,0) -> 0.17630379 | ... L14: =IFERROR('Historicals>'!L30,0) -> 0.22649113 | N14: =IFERROR(AVERAGE(C14:L14),0) -> 0.19743392 | O14: =IFERROR(MEDIAN(C14:L14),0) -> 0.18644572
B15: Net Profit Margin | C15: =IFERROR([1]HistoricalFS!C34,0) -> -0.11729792 | D15: =IFERROR([1]HistoricalFS!D34,0) -> -0.0071677156 | E15: =IFERROR([1]HistoricalFS!E34,0) -> -0.14809054 | F15: =IFERROR([1]HistoricalFS!F34,0) -> -0.15330146 | G15: =IFERROR([1]HistoricalFS!G34,0) -> -0.033075843 | H15: =IFERROR([1]HistoricalFS!H34,0) -> -0.010283669 | I15: =IFERROR([1]HistoricalFS!I34,0) -> -0.0077048894 | J15: =IFERROR([1]HistoricalFS!J34,0) -> -0.031399907 | ... L15: =IFERROR([1]HistoricalFS!L34,0) -> 0.027521204 | N15: =IFERROR(AVERAGE(C15:L15),0) -> -0.046674401 | O15: =IFERROR(MEDIAN(C15:L15),0) -> -0.020841788
B17: Sales Expense% Sales | C17: =IFERROR('Historicals>'!C10,0) -> 0.63892561 | D17: =IFERROR('Historicals>'!D10,0) -> 0.653423 | E17: =IFERROR('Historicals>'!E10,0) -> 0.65576762 | F17: =IFERROR('Historicals>'!F10,0) -> 0.62740385 | G17: =IFERROR('Historicals>'!G10,0) -> 0.61577254 | H17: =IFERROR('Historicals>'!H10,0) -> 0.58297104 | I17: =IFERROR('Historicals>'!I10,0) -> 0.5991156 | J17: =IFERROR('Historicals>'!J10,0) -> 0.60700541 | ... L17: =IFERROR('Historicals>'!L10,0) -> 0.57024137 | N17: =IFERROR(AVERAGE(C17:L17),0) -> 0.61231596 | O17: =IFERROR(MEDIAN(C17:L17),0) -> 0.61138898
B18: Depreciation% Sales | C18: =IFERROR('Historicals>'!C27,0) -> 0.034055983 | D18: =IFERROR('Historicals>'!D27,0) -> 0.035126349 | E18: =IFERROR('Historicals>'!E27,0) -> 0.040450731 | F18: =IFERROR('Historicals>'!F27,0) -> 0.033860759 | G18: =IFERROR('Historicals>'!G27,0) -> 0.037369065 | H18: =IFERROR('Historicals>'!H27,0) -> 0.033620234 | I18: =IFERROR('Historicals>'!I27,0) -> 0.02997228 | J18: =IFERROR('Historicals>'!J27,0) -> 0.036328939 | ... L18: =IFERROR('Historicals>'!L27,0) -> 0.043655037 | N18: =IFERROR(AVERAGE(C18:L18),0) -> 0.036413882 | O18: =IFERROR(MEDIAN(C18:L18),0) -> 0.035727644
B19: Operating% Sales | C19: =C13 -> 0.18414356 | D19: =D13 -> 0.17505151 | E19: =E13 -> 0.14018944 | F19: =F13 -> 0.17748296 | G19: =G13 -> 0.19829495 | H19: =H13 -> 0.29577189 | I19: =I13 -> 0.21038346 | J19: =J13 -> 0.18775085 | ... L19: =L13 -> 0.22948502 | N19: =IFERROR(AVERAGE(C19:L19),0) -> 0.20269689 | O19: =IFERROR(MEDIAN(C19:L19),0) -> 0.1930229
B21: Return on Capital Employed | C21: =IFERROR((SUM('Historicals>'!C29,'Historicals>'!C23)/SUM('Historicals>'!C49:C50)),0) -> 0.18827028 | D21: =IFERROR((SUM('Historicals>'!D29,'Historicals>'!D23)/SUM('Historicals>'!D49:D50)),0) -> 0.17256374 | E21: =IFERROR((SUM('Historicals>'!E29,'Historicals>'!E23)/SUM('Historicals>'!E49:E50)),0) -> 0.13696368 | F21: =IFERROR((SUM('Historicals>'!F29,'Historicals>'!F23)/SUM('Historicals>'!F49:F50)),0) -> 0.19703675 | G21: =IFERROR((SUM('Historicals>'!G29,'Historicals>'!G23)/SUM('Historicals>'!G49:G50)),0) -> 0.24515671 | H21: =IFERROR((SUM('Historicals>'!H29,'Historicals>'!H23)/SUM('Historicals>'!H49:H50)),0) -> 0.33381775 | I21: =IFERROR((SUM('Historicals>'!I29,'Historicals>'!I23)/SUM('Historicals>'!I49:I50)),0) -> 0.23898263 | J21: =IFERROR((SUM('Historicals>'!J29,'Historicals>'!J23)/SUM('Historicals>'!J49:J50)),0) -> 0.23838475 | ... L21: =IFERROR((SUM('Historicals>'!L29,'Historicals>'!L23)/SUM('Historicals>'!L49:L50)),0) -> 0.26188063 | N21: =IFERROR(AVERAGE(C21:L21),0) -> 0.22852944 | O21: =IFERROR(MEDIAN(C21:L21),0) -> 0.23868369
B22: Retained Earning% | C22: =IFERROR('Historicals>'!C46,0) -> 0.73931755 | D22: =IFERROR('Historicals>'!D46,0) -> 0.95401551 | E22: =IFERROR('Historicals>'!E46,0) -> 0.87954152 | F22: =IFERROR('Historicals>'!F46,0) -> 0.79316389 | G22: =IFERROR('Historicals>'!G46,0) -> 0.68783729 | H22: =IFERROR('Historicals>'!H46,0) -> 0.71564256 | I22: =IFERROR('Historicals>'!I46,0) -> 0.66961973 | J22: =IFERROR('Historicals>'!J46,0) -> 0.66492683 | ... L22: =IFERROR('Historicals>'!L46,0) -> 0.63410604 | N22: =IFERROR(AVERAGE(C22:L22),0) -> 0.73941433 | O22: =IFERROR(MEDIAN(C22:L22),0) -> 0.70173992
B23: Return on Equity% | C23: =IFERROR('Historicals>'!C35/SUM('Historicals>'!C49:C50),0) -> 0.13739304 | D23: =IFERROR('Historicals>'!D35/SUM('Historicals>'!D49:D50),0) -> 0.13523066 | E23: =IFERROR('Historicals>'!E35/SUM('Historicals>'!E49:E50),0) -> 0.096229753 | F23: =IFERROR('Historicals>'!F35/SUM('Historicals>'!F49:F50),0) -> 0.1310493 | G23: =IFERROR('Historicals>'!G35/SUM('Historicals>'!G49:G50),0) -> 0.18975402 | H23: =IFERROR('Historicals>'!H35/SUM('Historicals>'!H49:H50),0) -> 0.24783808 | I23: =IFERROR('Historicals>'!I35/SUM('Historicals>'!I49:I50),0) -> 0.1808887 | J23: =IFERROR('Historicals>'!J35/SUM('Historicals>'!J49:J50),0) -> 0.16529859 | ... L23: =IFERROR('Historicals>'!L35/SUM('Historicals>'!L49:L50),0) -> 0.19211434 | N23: =IFERROR(AVERAGE(C23:L23),0) -> 0.16648377 | O23: =IFERROR(MEDIAN(C23:L23),0) -> 0.17309364
B24: Self Sustained Growth Rate | C24: =IFERROR(C22*C23,0) -> 0.10157708 | D24: =IFERROR(D22*D23,0) -> 0.12901215 | E24: =IFERROR(E22*E23,0) -> 0.084638063 | F24: =IFERROR(F22*F23,0) -> 0.10394357 | G24: =IFERROR(G22*G23,0) -> 0.13051989 | H24: =IFERROR(H22*H23,0) -> 0.17736347 | I24: =IFERROR(I22*I23,0) -> 0.12112664 | J24: =IFERROR(J22*J23,0) -> 0.10991146 | ... L24: =IFERROR(L22*L23,0) -> 0.12182086 | N24: =IFERROR(AVERAGE(C24:L24),0) -> 0.1203919 | O24: =IFERROR(MEDIAN(C24:L24),0) -> 0.12147375
B25: Interest Coverage Ratio | C25: =IFERROR('Historicals>'!C23/'Historicals>'!C35,0) -> 0.06547802 | D25: =IFERROR('Historicals>'!D23/'Historicals>'!D35,0) -> 0.029119896 | E25: =IFERROR('Historicals>'!E23/'Historicals>'!E35,0) -> 0.025158593 | F25: =IFERROR('Historicals>'!F23/'Historicals>'!F35,0) -> 0.023972779 | G25: =IFERROR('Historicals>'!G23/'Historicals>'!G35,0) -> 0.011123756 | H25: =IFERROR('Historicals>'!H23/'Historicals>'!H35,0) -> 0.016141978 | I25: =IFERROR('Historicals>'!I23/'Historicals>'!I35,0) -> 0.013262874 | J25: =IFERROR('Historicals>'!J23/'Historicals>'!J35,0) -> 0.087926829 | ... L25: =IFERROR('Historicals>'!L23/'Historicals>'!L35,0) -> 0.017783775 | N25: =IFERROR(AVERAGE(C25:L25),0) -> 0.037018492 | O25: =IFERROR(MEDIAN(C25:L25),0) -> 0.024565686
B27: Debtor Turnover Ratio | C27: =IFERROR('Historicals>'!C6/'Historicals>'!C61,0) -> 4.4394073 | D27: =IFERROR('Historicals>'!D6/'Historicals>'!D61,0) -> 5.0542918 | E27: =IFERROR('Historicals>'!E6/'Historicals>'!E61,0) -> 4.6832042 | F27: =IFERROR('Historicals>'!F6/'Historicals>'!F61,0) -> 5.3312569 | G27: =IFERROR('Historicals>'!G6/'Historicals>'!G61,0) -> 5.1377414 | H27: =IFERROR('Historicals>'!H6/'Historicals>'!H61,0) -> 5.2504241 | I27: =IFERROR('Historicals>'!I6/'Historicals>'!I61,0) -> 4.3625763 | J27: =IFERROR('Historicals>'!J6/'Historicals>'!J61,0) -> 5.4693991 | ... L27: =IFERROR('Historicals>'!L6/'Historicals>'!L61,0) -> 4.8051093 | N27: =IFERROR(AVERAGE(C27:L27),0) -> 4.9605588 | O27: =IFERROR(MEDIAN(C27:L27),0) -> 5.0632345
B28: Creditor Turnover Ratio | C28: =IFERROR('Historicals>'!C6/'Historicals>'!C51,0) -> 6.2576776 | D28: =IFERROR('Historicals>'!D6/'Historicals>'!D51,0) -> 27.513099 | E28: =IFERROR('Historicals>'!E6/'Historicals>'!E51,0) -> 48.083988 | F28: =IFERROR('Historicals>'!F6/'Historicals>'!F51,0) -> 63.689922 | G28: =IFERROR('Historicals>'!G6/'Historicals>'!G51,0) -> 60.180739 | H28: =IFERROR('Historicals>'!H6/'Historicals>'!H51,0) -> 45.409515 | I28: =IFERROR('Historicals>'!I6/'Historicals>'!I51,0) -> 44.432551 | J28: =IFERROR('Historicals>'!J6/'Historicals>'!J51,0) -> 5.5014062 | ... L28: =IFERROR('Historicals>'!L6/'Historicals>'!L51,0) -> 140.4801 | N28: =IFERROR(AVERAGE(C28:L28),0) -> 45.077495 | O28: =IFERROR(MEDIAN(C28:L28),0) -> 44.921033
B29: Inventory Turnover Ratio | C29: =IFERROR('Historicals>'!C9/'Historicals>'!C62,0) -> 4.1138951 | D29: =IFERROR('Historicals>'!D9/'Historicals>'!D62,0) -> 4.38822 | E29: =IFERROR('Historicals>'!E9/'Historicals>'!E62,0) -> 4.3211996 | F29: =IFERROR('Historicals>'!F9/'Historicals>'!F62,0) -> 4.2293649 | G29: =IFERROR('Historicals>'!G9/'Historicals>'!G62,0) -> 3.9787017 | H29: =IFERROR('Historicals>'!H9/'Historicals>'!H62,0) -> 3.4270543 | I29: =IFERROR('Historicals>'!I9/'Historicals>'!I62,0) -> 3.5427847 | J29: =IFERROR('Historicals>'!J9/'Historicals>'!J62,0) -> 4.4406941 | ... L29: =IFERROR('Historicals>'!L9/'Historicals>'!L62,0) -> 4.2237598 | N29: =IFERROR(AVERAGE(C29:L29),0) -> 4.0635366 | O29: =IFERROR(MEDIAN(C29:L29),0) -> 4.1688275
B30: Fixed Asset Turnover Ratio | C30: =IFERROR('Historicals>'!C6/'Historicals>'!C55,0) -> 2.7494435 | D30: =IFERROR('Historicals>'!D6/'Historicals>'!D55,0) -> 1.9785264 | E30: =IFERROR('Historicals>'!E6/'Historicals>'!E55,0) -> 2.2023143 | F30: =IFERROR('Historicals>'!F6/'Historicals>'!F55,0) -> 2.6463531 | G30: =IFERROR('Historicals>'!G6/'Historicals>'!G55,0) -> 2.7250714 | H30: =IFERROR('Historicals>'!H6/'Historicals>'!H55,0) -> 3.2234199 | I30: =IFERROR('Historicals>'!I6/'Historicals>'!I55,0) -> 1.8984017 | J30: =IFERROR('Historicals>'!J6/'Historicals>'!J55,0) -> 1.6566352 | ... L30: =IFERROR('Historicals>'!L6/'Historicals>'!L55,0) -> 1.9906564 | N30: =IFERROR(AVERAGE(C30:L30),0) -> 2.2809088 | O30: =IFERROR(MEDIAN(C30:L30),0) -> 2.0964853
B31: Capital Turnover Ratio | C31: =IFERROR('Historicals>'!C6/SUM('Historicals>'!C49:C50),0) -> 1.0224103 | D31: =IFERROR('Historicals>'!D6/SUM('Historicals>'!D49:D50),0) -> 0.98578835 | E31: =IFERROR('Historicals>'!E6/SUM('Historicals>'!E49:E50),0) -> 0.97699005 | F31: =IFERROR('Historicals>'!F6/SUM('Historicals>'!F49:F50),0) -> 1.1101728 | G31: =IFERROR('Historicals>'!G6/SUM('Historicals>'!G49:G50),0) -> 1.2363235 | H31: =IFERROR('Historicals>'!H6/SUM('Historicals>'!H49:H50),0) -> 1.1286324 | I31: =IFERROR('Historicals>'!I6/SUM('Historicals>'!I49:I50),0) -> 1.1359383 | J31: =IFERROR('Historicals>'!J6/SUM('Historicals>'!J49:J50),0) -> 1.2696867 | ... L31: =IFERROR('Historicals>'!L6/SUM('Historicals>'!L49:L50),0) -> 1.1411666 | N31: =IFERROR(AVERAGE(C31:L31),0) -> 1.1198962 | O31: =IFERROR(MEDIAN(C31:L31),0) -> 1.1322854
B34: Debtor Days | C34: =IFERROR((365/C27),0) -> 82.218183 | D34: =IFERROR((365/D27),0) -> 72.215854 | E34: =IFERROR((365/E27),0) -> 77.938092 | F34: =IFERROR((365/F27),0) -> 68.464155 | G34: =IFERROR((365/G27),0) -> 71.042891 | H34: =IFERROR((365/H27),0) -> 69.518193 | I34: =IFERROR((365/I27),0) -> 83.666159 | J34: =IFERROR((365/J27),0) -> 66.734936 | ... L34: =IFERROR((365/L27),0) -> 75.960812 | N34: =IFERROR(AVERAGE(C34:L34),0) -> 73.972048 | O34: =IFERROR(MEDIAN(C34:L34),0) -> 72.088531
B35: Payable Days | C35: =IFERROR(365/C28,0) -> 58.328349 | D35: =IFERROR(365/D28,0) -> 13.266408 | E35: =IFERROR(365/E28,0) -> 7.5908846 | F35: =IFERROR(365/F28,0) -> 5.7308909 | G35: =IFERROR(365/G28,0) -> 6.0650634 | H35: =IFERROR(365/H28,0) -> 8.0379629 | I35: =IFERROR(365/I28,0) -> 8.2146982 | J35: =IFERROR(365/J28,0) -> 66.346673 | ... L35: =IFERROR(365/L28,0) -> 2.5982328 | N35: =IFERROR(AVERAGE(C35:L35),0) -> 21.574148 | O35: =IFERROR(MEDIAN(C35:L35),0) -> 8.1263306
B36: Inventory Days | C36: =IFERROR(365/C29,0) -> 88.723701 | D36: =IFERROR(365/D29,0) -> 83.177233 | E36: =IFERROR(365/E29,0) -> 84.467285 | F36: =IFERROR(365/F29,0) -> 86.301373 | G36: =IFERROR(365/G29,0) -> 91.738468 | H36: =IFERROR(365/H29,0) -> 106.50546 | I36: =IFERROR(365/I29,0) -> 103.0263 | J36: =IFERROR(365/J29,0) -> 82.194358 | ... L36: =IFERROR(365/L29,0) -> 86.415898 | N36: =IFERROR(AVERAGE(C36:L36),0) -> 90.449676 | O36: =IFERROR(MEDIAN(C36:L36),0) -> 87.5698
B37: Cash Conversion Cycle (in days) | C37: =SUM(C34,C36)-C35 -> 112.61354 | D37: =SUM(D34,D36)-D35 -> 142.12668 | E37: =SUM(E34,E36)-E35 -> 154.81449 | F37: =SUM(F34,F36)-F35 -> 149.03464 | G37: =SUM(G34,G36)-G35 -> 156.7163 | H37: =SUM(H34,H36)-H35 -> 167.98569 | I37: =SUM(I34,I36)-I35 -> 178.47776 | J37: =SUM(J34,J36)-J35 -> 82.582621 | ... L37: =SUM(L34,L36)-L35 -> 159.77848 | N37: =IFERROR(AVERAGE(C37:L37),0) -> 142.84758 | O37: =IFERROR(MEDIAN(C37:L37),0) -> 151.92456
B39: CFO/Sales | C39: =IFERROR('Historicals>'!C72/'Historicals>'!C6,0) -> 0.11566807 | D39: =IFERROR('Historicals>'!D72/'Historicals>'!D6,0) -> 0.14952131 | E39: =IFERROR('Historicals>'!E72/'Historicals>'!E6,0) -> 0.087334384 | F39: =IFERROR('Historicals>'!F72/'Historicals>'!F6,0) -> 0.11806232 | G39: =IFERROR('Historicals>'!G72/'Historicals>'!G6,0) -> 0.15551661 | H39: =IFERROR('Historicals>'!H72/'Historicals>'!H6,0) -> 0.15422126 | I39: =IFERROR('Historicals>'!I72/'Historicals>'!I6,0) -> 0.07012507 | J39: =IFERROR('Historicals>'!J72/'Historicals>'!J6,0) -> 0.19877559 | ... L39: =IFERROR('Historicals>'!L72/'Historicals>'!L6,0) -> 0.23022009 | N39: =IFERROR(AVERAGE(C39:L39),0) -> 0.1509341 | O39: =IFERROR(MEDIAN(C39:L39),0) -> 0.15187128
B40: CFO/Total Assets | C40: =IFERROR('Historicals>'!C72/'Historicals>'!C66,0) -> 0.084968986 | D40: =IFERROR('Historicals>'!D72/'Historicals>'!D66,0) -> 0.12006882 | E40: =IFERROR('Historicals>'!E72/'Historicals>'!E66,0) -> 0.069684042 | F40: =IFERROR('Historicals>'!F72/'Historicals>'!F66,0) -> 0.10826195 | G40: =IFERROR('Historicals>'!G72/'Historicals>'!G66,0) -> 0.15215162 | H40: =IFERROR('Historicals>'!H72/'Historicals>'!H66,0) -> 0.14118153 | I40: =IFERROR('Historicals>'!I72/'Historicals>'!I66,0) -> 0.065360231 | J40: =IFERROR('Historicals>'!J72/'Historicals>'!J66,0) -> 0.17646926 | ... L40: =IFERROR('Historicals>'!L72/'Historicals>'!L66,0) -> 0.21147101 | N40: =IFERROR(AVERAGE(C40:L40),0) -> 0.13304574 | O40: =IFERROR(MEDIAN(C40:L40),0) -> 0.13062517
B41: CFO/Total Debt | C41: =IFERROR('Historicals>'!C72/SUM('Historicals>'!C51:C52),0) -> 0.30183472 | D41: =IFERROR('Historicals>'!D72/SUM('Historicals>'!D51:D52),0) -> 0.64761414 | E41: =IFERROR('Historicals>'!E72/SUM('Historicals>'!E51:E52),0) -> 0.38014588 | F41: =IFERROR('Historicals>'!F72/SUM('Historicals>'!F51:F52),0) -> 0.62215381 | G41: =IFERROR('Historicals>'!G72/SUM('Historicals>'!G51:G52),0) -> 0.72921345 | H41: =IFERROR('Historicals>'!H72/SUM('Historicals>'!H51:H52),0) -> 0.74743736 | I41: =IFERROR('Historicals>'!I72/SUM('Historicals>'!I51:I52),0) -> 0.36415046 | J41: =IFERROR('Historicals>'!J72/SUM('Historicals>'!J51:J52),0) -> 0.58669166 | ... L41: =IFERROR('Historicals>'!L72/SUM('Historicals>'!L51:L52),0) -> 1.0840825 | N41: =IFERROR(AVERAGE(C41:L41),0) -> 0.62154931 | O41: =IFERROR(MEDIAN(C41:L41),0) -> 0.63488397

Sheet Forecasting
B3: ='Data Sheet'!$B$1&" - "&'Data Sheet'!A17& " Forecasting" -> J B CHEMICALS & PHARMACEUTICALS LTD - Sales Forecasting | G3: ='Data Sheet'!$B$1&" - "&'Historicals>'!B20&" Forecasting" -> J B CHEMICALS & PHARMACEUTICALS LTD - EBITDA Forecasting | L3: ='Data Sheet'!$B$1&" - "&'Historicals>'!B40&" Forecasting" -> J B CHEMICALS & PHARMACEUTICALS LTD - EPS Forecasting
B4: Year Weight | C4: Year | D4: Sales | E4: Sales Growth | G4: Year Weight | H4: Year | I4: EBITDA | J4: EBITDA Growth | L4: Year Weight | M4: Year | N4: EPS | O4: EPS Growth
B5: 1 | C5: ='Data Sheet'!$B$16 -> 42460 | D5: {=TRANSPOSE('Data Sheet'!B17:K17)} -> 1210.36 | G5: 1 | H5: ='Data Sheet'!$B$16 -> 42460 | I5: {=TRANSPOSE('Historicals>'!C20:L20)} -> 264.1 | L5: 1 | M5: ='Data Sheet'!$B$16 -> 42460 | N5: {=TRANSPOSE('Historicals>'!C40:L40)} -> 9.5902123
B6: =B5+1 -> 2 | C6: =C5+365 -> 42825 | D6: 1344.29 | E6: =IFERROR(D6/D5-1,0) -> 0.11065303 | G6: =G5+1 -> 2 | H6: =H5+365 -> 42825 | I6: 282.54 | J6: =IFERROR(I6/I5-1,0) -> 0.069822037 | L6: =L5+1 -> 2 | M6: =M5+365 -> 42825 | N6: 10.873231 | O6: =IFERROR(N6/N5-1,0) -> 0.1337842
B7: =B6+1 -> 3 | C7: =C6+365 -> 43190 | D7: 1408.38 | E7: =IFERROR(D7/D6-1,0) -> 0.047675725 | G7: =G6+1 -> 3 | H7: =H6+365 -> 43190 | I7: 254.41 | J7: =IFERROR(I7/I6-1,0) -> -0.099561124 | L7: =L6+1 -> 3 | M7: =M6+365 -> 43190 | N7: 8.3016158 | O7: =IFERROR(N7/N6-1,0) -> -0.23650884
B8: =B7+1 -> 4 | C8: =C7+365 -> 43555 | D8: 1643.2 | E8: =IFERROR(D8/D7-1,0) -> 0.16673057 | G8: =G7+1 -> 4 | H8: =H7+365 -> 43555 | I8: 347.28 | J8: =IFERROR(I8/I7-1,0) -> 0.36504068 | L8: =L7+1 -> 4 | M8: =M7+365 -> 43555 | N8: 12.085358 | O8: =IFERROR(N8/N7-1,0) -> 0.45578386
B9: =B8+1 -> 5 | C9: =C8+365 -> 43920 | D9: 1774.73 | E9: =IFERROR(D9/D8-1,0) -> 0.080045034 | G9: =G8+1 -> 5 | H9: =H8+365 -> 43920 | I9: 418.24 | J9: =IFERROR(I9/I8-1,0) -> 0.2043308 | L9: =L8+1 -> 5 | M9: =M8+365 -> 43920 | N9: 17.619017 | O9: =IFERROR(N9/N8-1,0) -> 0.45788122
B10: =B9+1 -> 6 | C10: =C9+365 -> 44285 | D10: 2042.52 | E10: =IFERROR(D10/D9-1,0) -> 0.15089056 | G10: =G9+1 -> 6 | H10: =H9+365 -> 44285 | I10: 672.79 | J10: =IFERROR(I10/I9-1,0) -> 0.60862184 | L10: =L9+1 -> 6 | M10: =M9+365 -> 44285 | N10: 29.011643 | O10: =IFERROR(N10/N9-1,0) -> 0.64660964
B11: =B10+1 -> 7 | C11: =C10+365 -> 44650 | D11: 2424.24 | E11: =IFERROR(D11/D10-1,0) -> 0.18688679 | G11: =G10+1 -> 7 | H11: =H10+365 -> 44650 | I11: 582.68 | J11: =IFERROR(I11/I10-1,0) -> -0.13393481 | L11: =L10+1 -> 7 | M11: =M10+365 -> 44650 | N11: 24.970246 | O11: =IFERROR(N11/N10-1,0) -> -0.1393026
B12: =B11+1 -> 8 | C12: =C11+365 -> 45015 | D12: 3149.28 | E12: =IFERROR(D12/D11-1,0) -> 0.2990793 | G12: =G11+1 -> 8 | H12: =H11+365 -> 45015 | I12: 705.69 | J12: =IFERROR(I12/I11-1,0) -> 0.21111073 | L12: =L11+1 -> 8 | M12: =M11+365 -> 45015 | N12: 26.485788 | O12: =IFERROR(N12/N11-1,0) -> 0.060693929
B13: =B12+1 -> 9 | C13: =C12+365 -> 45380 | D13: 3484.18 | E13: =IFERROR(D13/D12-1,0) -> 0.10634177 | G13: =G12+1 -> 9 | H13: =H12+365 -> 45380 | I13: 934.16 | J13: =IFERROR(I13/I12-1,0) -> 0.32375406 | L13: =L12+1 -> 9 | M13: =M12+365 -> 45380 | N13: 35.607603 | O13: =IFERROR(N13/N12-1,0) -> 0.34440414
B14: =B13+1 -> 10 | C14: =C13+365 -> 45745 | D14: 3917.99 | E14: =IFERROR(D14/D13-1,0) -> 0.12450849 | G14: =G13+1 -> 10 | H14: =H13+365 -> 45745 | I14: 1070.16 | J14: =IFERROR(I14/I13-1,0) -> 0.14558534 | L14: =L13+1 -> 10 | M14: =M13+365 -> 45745 | N14: 42.362877 | O14: =IFERROR(N14/N13-1,0) -> 0.18971438
B15: =B14+1 -> 11 | C15: =C14+365 -> 46110 | D15: =FORECAST(B15,$D$5:$D$14,$B$5:$B$14) -> 3928.694 | E15: =IFERROR(D15/D14-1,0) -> 0.0027320131 | G15: =G14+1 -> 11 | H15: =H14+365 -> 46110 | I15: =FORECAST(G15,$I$5:$I$14,$G$5:$G$14) -> 1054.306 | J15: =IFERROR(I15/I14-1,0) -> -0.014814607 | L15: =L14+1 -> 11 | M15: =M14+365 -> 46110 | N15: =FORECAST(L15,$N$5:$N$14,$L$5:$L$14) -> 41.99285 | O15: =IFERROR(N15/N14-1,0) -> -0.0087346959
B16: =B15+1 -> 12 | C16: =C15+365 -> 46475 | D16: =FORECAST(B16,$D$5:$D$14,$B$5:$B$14) -> 4235.7444 | E16: =IFERROR(D16/D15-1,0) -> 0.078155836 | G16: =G15+1 -> 12 | H16: =H15+365 -> 46475 | I16: =FORECAST(G16,$I$5:$I$14,$G$5:$G$14) -> 1145.4153 | J16: =IFERROR(I16/I15-1,0) -> 0.086416347 | L16: =L15+1 -> 12 | M16: =M15+365 -> 46475 | N16: =FORECAST(L16,$N$5:$N$14,$L$5:$L$14) -> 45.68414 | O16: =IFERROR(N16/N15-1,0) -> 0.087902805
B17: =B16+1 -> 13 | C17: =C16+365 -> 46840 | D17: =FORECAST(B17,$D$5:$D$14,$B$5:$B$14) -> 4542.7947 | E17: =IFERROR(D17/D16-1,0) -> 0.072490296 | G17: =G16+1 -> 13 | H17: =H16+365 -> 46840 | I17: =FORECAST(G17,$I$5:$I$14,$G$5:$G$14) -> 1236.5245 | J17: =IFERROR(I17/I16-1,0) -> 0.079542568 | L17: =L16+1 -> 13 | M17: =M16+365 -> 46840 | N17: =FORECAST(L17,$N$5:$N$14,$L$5:$L$14) -> 49.375429 | O17: =IFERROR(N17/N16-1,0) -> 0.080800237
B18: =B17+1 -> 14 | C18: =C17+365 -> 47205 | D18: =FORECAST(B18,$D$5:$D$14,$B$5:$B$14) -> 4849.8451 | E18: =IFERROR(D18/D17-1,0) -> 0.067590631 | G18: =G17+1 -> 14 | H18: =H17+365 -> 47205 | I18: =FORECAST(G18,$I$5:$I$14,$G$5:$G$14) -> 1327.6338 | J18: =IFERROR(I18/I17-1,0) -> 0.073681734 | L18: =L17+1 -> 14 | M18: =M17+365 -> 47205 | N18: =FORECAST(L18,$N$5:$N$14,$L$5:$L$14) -> 53.066718 | O18: =IFERROR(N18/N17-1,0) -> 0.07475964
B19: =B18+1 -> 15 | C19: =C18+365 -> 47570 | D19: =FORECAST(B19,$D$5:$D$14,$B$5:$B$14) -> 5156.8955 | E19: =IFERROR(D19/D18-1,0) -> 0.063311375 | G19: =G18+1 -> 15 | H19: =H18+365 -> 47570 | I19: =FORECAST(G19,$I$5:$I$14,$G$5:$G$14) -> 1418.7431 | J19: =IFERROR(I19/I18-1,0) -> 0.068625303 | L19: =L18+1 -> 15 | M19: =M18+365 -> 47570 | N19: =FORECAST(L19,$N$5:$N$14,$L$5:$L$14) -> 56.758008 | O19: =IFERROR(N19/N18-1,0) -> 0.069559404

Sheet Data >
B2: ='Data Sheet'!B1&" - Sales Forecasting" -> J B CHEMICALS & PHARMACEUTICALS LTD - Sales Forecasting | L2: ='Data Sheet'!B1&" - EBITDA Forecasting" -> J B CHEMICALS & PHARMACEUTICALS LTD - EBITDA Forecasting | Q2: ='Data Sheet'!B1&" - EPS Forecasting" -> J B CHEMICALS & PHARMACEUTICALS LTD - EPS Forecasting
B3: Year Weight | C3: Year | D3: Sales | E3: Sales Growth | L3: Year Weight | M3: Year | N3: Sales | O3: Sales Growth | Q3: Year Weight | R3: Year | S3: Sales | T3: Sales Growth
B4: 1 | C4: ='[1]Data Sheet'!$B$16 -> 42460 | D4: 1210.36 | L4: 1 | M4: ='[1]Data Sheet'!$B$16 -> 42460 | N4: {=TRANSPOSE([1]HistoricalFS!C18:L18)} -> 2105.23 | Q4: 1 | R4: ='[1]Data Sheet'!$B$16 -> 42460 | S4: {=TRANSPOSE([1]HistoricalFS!C38:L38)} -> -12.791614
B5: =B4+1 -> 2 | C5: =C4+365 -> 42825 | D5: 1344.29 | E5: =IFERROR(D5/D4-1,0) -> 0.11065303 | L5: =L4+1 -> 2 | M5: =M4+365 -> 42825 | N5: 5473.27 | O5: =IFERROR(N5/N4-1,0) -> 1.5998442 | Q5: =Q4+1 -> 2 | R5: =R4+365 -> 42825 | S5: -0.73107069 | T5: =IFERROR(S5/S4-1,0) -> -0.94284766
B6: =B5+1 -> 3 | C6: =C5+365 -> 43190 | D6: 1408.38 | E6: =IFERROR(D6/D5-1,0) -> 0.047675725 | L6: =L5+1 -> 3 | M6: =M5+365 -> 43190 | N6: 2294.83 | O6: =IFERROR(N6/N5-1,0) -> -0.58072048 | Q6: =Q5+1 -> 3 | R6: =R5+365 -> 43190 | S6: -14.695319 | T6: =IFERROR(S6/S5-1,0) -> 19.101092
B7: =B6+1 -> 4 | C7: =C6+365 -> 43555 | D7: 1643.2 | E7: =IFERROR(D7/D6-1,0) -> 0.16673057 | L7: =L6+1 -> 4 | M7: =M6+365 -> 43555 | N7: 3069.91 | O7: =IFERROR(N7/N6-1,0) -> 0.33775051 | Q7: =Q6+1 -> 4 | R7: =R6+365 -> 43555 | S7: -16.935855 | T7: =IFERROR(S7/S6-1,0) -> 0.15246592
B8: =B7+1 -> 5 | C8: =C7+365 -> 43920 | D8: 1774.73 | E8: =IFERROR(D8/D7-1,0) -> 0.080045034 | L8: =L7+1 -> 5 | M8: =M7+365 -> 43920 | N8: 6805.07 | O8: =IFERROR(N8/N7-1,0) -> 1.2167002 | Q8: =Q7+1 -> 5 | R8: =R7+365 -> 43920 | S8: -3.5629621 | T8: =IFERROR(S8/S7-1,0) -> -0.78962018
B9: =B8+1 -> 6 | C9: =C8+365 -> 44285 | D9: 2042.52 | E9: =IFERROR(D9/D8-1,0) -> 0.15089056 | L9: =L8+1 -> 6 | M9: =M8+365 -> 44285 | N9: 6920.9 | O9: =IFERROR(N9/N8-1,0) -> 0.017021133 | Q9: =Q8+1 -> 6 | R9: =R8+365 -> 44285 | S9: -1.0525146 | T9: =IFERROR(S9/S8-1,0) -> -0.70459562
B10: =B9+1 -> 7 | C10: =C9+365 -> 44650 | D10: 2424.24 | E10: =IFERROR(D10/D9-1,0) -> 0.18688679 | L10: =L9+1 -> 7 | M10: =M9+365 -> 44650 | N10: 7030.89 | O10: =IFERROR(N10/N9-1,0) -> 0.015892442 | Q10: =Q9+1 -> 7 | R10: =R9+365 -> 44650 | S10: -1.0324226 | T10: =IFERROR(S10/S9-1,0) -> -0.01908953
B11: =B10+1 -> 8 | C11: =C10+365 -> 45015 | D11: 3149.28 | E11: =IFERROR(D11/D10-1,0) -> 0.2990793 | L11: =L10+1 -> 8 | M11: =M10+365 -> 45015 | N11: 7727.76 | O11: =IFERROR(N11/N10-1,0) -> 0.099115475 | Q11: =Q10+1 -> 8 | R11: =R10+365 -> 45015 | S11: -5.4155165 | T11: =IFERROR(S11/S10-1,0) -> 4.2454455
B12: =B11+1 -> 9 | C12: =C11+365 -> 45380 | D12: 3484.18 | E12: =IFERROR(D12/D11-1,0) -> 0.10634177 | L12: =L11+1 -> 9 | M12: =M11+365 -> 45380 | N12: 10735.28 | O12: =IFERROR(N12/N11-1,0) -> 0.38918393 | Q12: =Q11+1 -> 9 | R12: =R11+365 -> 45380 | S12: 2.7032517 | T12: =IFERROR(S12/S11-1,0) -> -1.4991678
B13: =B12+1 -> 10 | C13: =C12+365 -> 45745 | D13: 3917.99 | E13: =IFERROR(D13/D12-1,0) -> 0.12450849 | L13: =L12+1 -> 10 | M13: =M12+365 -> 45745 | N13: 12165.59 | O13: =IFERROR(N13/N12-1,0) -> 0.13323453 | Q13: =Q12+1 -> 10 | R13: =R12+365 -> 45745 | S13: 5.6396582 | T13: =IFERROR(S13/S12-1,0) -> 1.0862498
B14: =B13+1 -> 11 | C14: =C13+365 -> 46110 | D14: =FORECAST(B14,$D$4:$D$13,$B$4:$B$13) -> 3928.694 | E14: =IFERROR(D14/D13-1,0) -> 0.0027320131 | L14: =L13+1 -> 11 | M14: =M13+365 -> 46110 | N14: =FORECAST(L14,$N$4:$N$13,$L$4:$L$13) -> 11984.231 | O14: =IFERROR(N14/N13-1,0) -> -0.014907566 | Q14: =Q13+1 -> 11 | R14: =R13+365 -> 46110 | S14: =FORECAST(Q14,S4:S13,Q4:Q13) -> 4.7639457 | T14: =IFERROR(S14/S13-1,0) -> -0.15527759
B15: =B14+1 -> 12 | C15: =C14+365 -> 46475 | D15: =FORECAST(B15,$D$4:$D$13,$B$4:$B$13) -> 4235.7444 | E15: =IFERROR(D15/D14-1,0) -> 0.078155836 | L15: =L14+1 -> 12 | M15: =M14+365 -> 46475 | N15: =FORECAST(L15,$N$4:$N$13,$L$4:$L$13) -> 12993.568 | O15: =IFERROR(N15/N14-1,0) -> 0.084222157 | Q15: =Q14+1 -> 12 | R15: =R14+365 -> 46475 | S15: =FORECAST(Q15,S5:S14,Q5:Q14) -> 6.4500512 | T15: =IFERROR(S15/S14-1,0) -> 0.35393046
B16: =B15+1 -> 13 | C16: =C15+365 -> 46840 | D16: =FORECAST(B16,$D$4:$D$13,$B$4:$B$13) -> 4542.7947 | E16: =IFERROR(D16/D15-1,0) -> 0.072490296 | L16: =L15+1 -> 13 | M16: =M15+365 -> 46840 | N16: =FORECAST(L16,$N$4:$N$13,$L$4:$L$13) -> 14002.906 | O16: =IFERROR(N16/N15-1,0) -> 0.077679797 | Q16: =Q15+1 -> 13 | R16: =R15+365 -> 46840 | S16: =FORECAST(Q16,S6:S15,Q6:Q15) -> 10.856373 | T16: =IFERROR(S16/S15-1,0) -> 0.68314527
B17: =B16+1 -> 14 | C17: =C16+365 -> 47205 | D17: =FORECAST(B17,$D$4:$D$13,$B$4:$B$13) -> 4849.8451 | E17: =IFERROR(D17/D16-1,0) -> 0.067590631 | L17: =L16+1 -> 14 | M17: =M16+365 -> 47205 | N17: =FORECAST(L17,$N$4:$N$13,$L$4:$L$13) -> 15012.244 | O17: =IFERROR(N17/N16-1,0) -> 0.072080591 | Q17: =Q16+1 -> 14 | R17: =R16+365 -> 47205 | S17: =FORECAST(Q17,S7:S16,Q7:Q16) -> 12.822683 | T17: =IFERROR(S17/S16-1,0) -> 0.18112031
B18: =B17+1 -> 15 | C18: =C17+365 -> 47570 | D18: =FORECAST(B18,$D$4:$D$13,$B$4:$B$13) -> 5156.8955 | E18: =IFERROR(D18/D17-1,0) -> 0.063311375 | L18: =L17+1 -> 15 | M18: =M17+365 -> 47570 | N18: =FORECAST(L18,$N$4:$N$13,$L$4:$L$13) -> 16021.582 | O18: =IFERROR(N18/N17-1,0) -> 0.067234303 | Q18: =Q17+1 -> 15 | R18: =R17+365 -> 47570 | S18: =FORECAST(Q18,S8:S17,Q8:Q17) -> 13.274594 | T18: =IFERROR(S18/S17-1,0) -> 0.035243112
G20: SUMMARY OUTPUT
G22: Regression Statistics
G23: Multiple R | H23: 0.96283984
G24: R Square | H24: 0.92706055
G25: Adjusted R Square | H25: 0.91794312
G26: Standard Error | H26: 276.57874
G27: Observations | H27: 10
G29: ANOVA
H30: df | I30: SS | J30: MS | K30: F | L30: Significance F
G31: Regression | H31: 1 | I31: 7778093.9 | J31: 7778093.9 | K31: 101.68002 | L31: 7.9760781e-06
G32: Residual | H32: 8 | I32: 611966.38 | J32: 76495.798
G33: Total | H33: 9 | I33: 8390060.3
H35: Coefficients | I35: Standard Error | J35: t Stat | K35: P-value | L35: Lower 95% | M35: Upper 95% | N35: Lower 95.0% | O35: Upper 95.0%
G36: Intercept | H36: 551.14 | I36: 188.93925 | J36: 2.9170223 | K36: 0.019379465 | L36: 115.44532 | M36: 986.83468 | N36: 115.44532 | O36: 986.83468
G37: X Variable 1 | H37: 307.05036 | I37: 30.450317 | J37: 10.083651 | K37: 7.9760781e-06 | L37: 236.83181 | M37: 377.26892 | N37: 236.83181 | O37: 377.26892

Sheet Data Sheet
A1: COMPANY NAME | B1: J B CHEMICALS & PHARMACEUTICALS LTD | E1: =IF(B2<>B3, "A NEW VERSION OF THE WORKSHEET IS AVAILABLE", "")
A2: LATEST VERSION | B2: 2.1 | E2: PLEASE DO NOT MAKE ANY CHANGES TO THIS SHEET
A3: CURRENT VERSION | B3: 2.1
A5: META
A6: Number of shares | B6: =IF(B9>0, B9/B8, 0) -> 16.057346
A7: Face Value | B7: 1
A8: Current Price | B8: 1846
A9: Market Capitalization | B9: 29641.86
A15: PROFIT & LOSS
A16: Report Date | B16: 42460 | C16: 42825 | D16: 43190 | E16: 43555 | F16: 43921 | G16: 44286 | H16: 44651 | I16: 45016 | J16: 45382 | K16: 45747
A17: Sales | B17: 1210.36 | C17: 1344.29 | D17: 1408.38 | E17: 1643.2 | F17: 1774.73 | G17: 2042.52 | H17: 2424.24 | I17: 3149.28 | J17: 3484.18 | K17: 3917.99
A18: Raw Material Cost | B18: 483.71 | C18: 519.54 | D18: 544.41 | E18: 615.76 | F18: 634.79 | G18: 742.76 | H18: 860.38 | I18: 1179.2 | J18: 1228.9 | K18: 1316.97
A19: Change in Inventory | B19: 13.51 | C19: -8.43 | D19: 6.59 | E19: 19.3 | F19: 3.99 | G19: 41.26 | H19: 17.45 | I19: 11 | J19: 46.85 | K19: 0.43
A20: Power and Fuel | B20: 55.28 | C20: 54.89 | D20: 58.28 | E20: 63.29 | F20: 61.54 | G20: 62.6 | H20: 71.47 | I20: 91.54 | J20: 88.08 | K20: 83.95
A21: Other Mfr. Exp | B21: 71.91 | C21: 77.7 | D21: 75.92 | E21: 82.54 | F21: 77.08 | G21: 84.7 | H21: 97.36 | I21: 106.14 | J21: 120.97 | K21: 143.86
A22: Employee Cost | B22: 175.94 | C22: 217.83 | D22: 251.55 | E22: 288.66 | F22: 323.41 | G22: 341.93 | H22: 440.64 | I22: 545.75 | J22: 603.71 | K22: 689.85
