Workbook
Name UPDATE: 'Data Sheet'!$E$1

Sheet Profit & Loss
A1: ='Data Sheet'!B1 -> TATA POWER COMPANY LTD | H1: =UPDATE | M1: SCREENER.IN
A3: Narration | B3: ='Data Sheet'!B16 -> 42460 | C3: ='Data Sheet'!C16 -> 42825 | D3: ='Data Sheet'!D16 -> 43190 | E3: ='Data Sheet'!E16 -> 43555 | F3: ='Data Sheet'!F16 -> 43921 | G3: ='Data Sheet'!G16 -> 44286 | H3: ='Data Sheet'!H16 -> 44651 | I3: ='Data Sheet'!I16 -> 45016 | ... K3: ='Data Sheet'!K16 -> 45747 | L3: Trailing | M3: Best Case | N3: Worst Case
A4: Sales | B4: ='Data Sheet'!B17 -> 29494.3 | C4: ='Data Sheet'!C17 -> 27587.59 | D4: ='Data Sheet'!D17 -> 26840.27 | E4: ='Data Sheet'!E17 -> 29881.06 | F4: ='Data Sheet'!F17 -> 29136.37 | G4: ='Data Sheet'!G17 -> 32703.31 | H4: ='Data Sheet'!H17 -> 42815.67 | I4: ='Data Sheet'!I17 -> 55109.08 | ... K4: ='Data Sheet'!K17 -> 65478.24 | L4: =SUM(#REF!) -> #REF! | M4: =$K4+M23*K4 -> 75438.854 | N4: =$K4+N23*L4 -> #REF!
A5: Expenses | B5: =SUM('Data Sheet'!B18,'Data Sheet'!B20:B24, -1*'Data Sheet'!B19) -> 27389.07 | C5: =SUM('Data Sheet'!C18,'Data Sheet'!C20:C24, -1*'Data Sheet'!C19) -> 22114.32 | D5: =SUM('Data Sheet'!D18,'Data Sheet'!D20:D24, -1*'Data Sheet'!D19) -> 24545.44 | E5: =SUM('Data Sheet'!E18,'Data Sheet'!E20:E24, -1*'Data Sheet'!E19) -> 26811.15 | F5: =SUM('Data Sheet'!F18,'Data Sheet'!F20:F24, -1*'Data Sheet'!F19) -> 22331.3 | G5: =SUM('Data Sheet'!G18,'Data Sheet'!G20:G24, -1*'Data Sheet'!G19) -> 25782.41 | H5: =SUM('Data Sheet'!H18,'Data Sheet'!H20:H24, -1*'Data Sheet'!H19) -> 35784.78 | I5: =SUM('Data Sheet'!I18,'Data Sheet'!I20:I24, -1*'Data Sheet'!I19) -> 47381.32 | ... K5: =SUM('Data Sheet'!K18,'Data Sheet'!K20:K24, -1*'Data Sheet'!K19) -> 53312.65 | L5: =SUM(#REF!) -> #REF! | M5: =M4-M6 -> #REF! | N5: =N4-N6 -> #REF!
A6: Operating Profit | B6: =B4-B5 -> 2105.23 | C6: =C4-C5 -> 5473.27 | D6: =D4-D5 -> 2294.83 | E6: =E4-E5 -> 3069.91 | F6: =F4-F5 -> 6805.07 | G6: =G4-G5 -> 6920.9 | H6: =H4-H5 -> 7030.89 | I6: =I4-I5 -> 7727.76 | ... K6: =K4-K5 -> 12165.59 | L6: =SUM(#REF!) -> #REF! | M6: =M4*M24 -> #REF! | N6: =N4*N24 -> #REF!
A7: Other Income | B7: ='Data Sheet'!B25 -> 4060.02 | C7: ='Data Sheet'!C25 -> 1297.37 | D7: ='Data Sheet'!D25 -> 6585.64 | E7: ='Data Sheet'!E25 -> 7186.47 | F7: ='Data Sheet'!F25 -> 2280.15 | G7: ='Data Sheet'!G25 -> 1774.96 | H7: ='Data Sheet'!H25 -> 2485.5 | I7: ='Data Sheet'!I25 -> 5540.09 | ... K7: ='Data Sheet'!K25 -> 2973.33 | L7: =SUM(#REF!) -> #REF! | M7: 0 | N7: 0
A8: Depreciation | B8: ='Data Sheet'!B26 -> 1648.73 | C8: ='Data Sheet'!C26 -> 1955.59 | D8: ='Data Sheet'!D26 -> 2346.17 | E8: ='Data Sheet'!E26 -> 2393.13 | F8: ='Data Sheet'!F26 -> 2633.56 | G8: ='Data Sheet'!G26 -> 2744.94 | H8: ='Data Sheet'!H26 -> 3122.2 | I8: ='Data Sheet'!I26 -> 3439.2 | ... K8: ='Data Sheet'!K26 -> 4116.86 | L8: =SUM(#REF!) -> #REF! | M8: =+$L8 -> #REF! | N8: =+$L8 -> #REF!
A9: Interest | B9: ='Data Sheet'!B27 -> 3235.81 | C9: ='Data Sheet'!C27 -> 3364.96 | D9: ='Data Sheet'!D27 -> 3761.48 | E9: ='Data Sheet'!E27 -> 4170 | F9: ='Data Sheet'!F27 -> 4493.73 | G9: ='Data Sheet'!G27 -> 4010.39 | H9: ='Data Sheet'!H27 -> 3859.02 | I9: ='Data Sheet'!I27 -> 4371.65 | ... K9: ='Data Sheet'!K27 -> 4702.44 | L9: =SUM(#REF!) -> #REF! | M9: =+$L9 -> #REF! | N9: =+$L9 -> #REF!
A10: Profit before tax | B10: ='Data Sheet'!B28 -> 1280.71 | C10: ='Data Sheet'!C28 -> 1450.09 | D10: ='Data Sheet'!D28 -> 2772.82 | E10: ='Data Sheet'!E28 -> 3693.25 | F10: ='Data Sheet'!F28 -> 1957.93 | G10: ='Data Sheet'!G28 -> 1940.53 | H10: ='Data Sheet'!H28 -> 2535.17 | I10: ='Data Sheet'!I28 -> 5457 | ... K10: ='Data Sheet'!K28 -> 6319.62 | L10: =SUM(#REF!) -> #REF! | M10: =M6+M7-SUM(M8:M9) -> #REF! | N10: =N6+N7-SUM(N8:N9) -> #REF!
A11: Tax | B11: ='Data Sheet'!B29 -> 680.31 | C11: ='Data Sheet'!C29 -> 350.46 | D11: ='Data Sheet'!D29 -> 161.97 | E11: ='Data Sheet'!E29 -> 1087.59 | F11: ='Data Sheet'!F29 -> 641.49 | G11: ='Data Sheet'!G29 -> 501.88 | H11: ='Data Sheet'!H29 -> 379.56 | I11: ='Data Sheet'!I29 -> 1647.33 | ... K11: ='Data Sheet'!K29 -> 1544.25 | L11: =SUM(#REF!) -> #REF! | M11: =IF($L10>0,$L11/$L10,0) -> #REF! | N11: =IF($L10>0,$L11/$L10,0) -> #REF!
A12: Net profit | B12: ='Data Sheet'!B30 -> 662.2 | C12: ='Data Sheet'!C30 -> 896.55 | D12: ='Data Sheet'!D30 -> 2408.3 | E12: ='Data Sheet'!E30 -> 2356.19 | F12: ='Data Sheet'!F30 -> 1017.38 | G12: ='Data Sheet'!G30 -> 1127.38 | H12: ='Data Sheet'!H30 -> 1741.46 | I12: ='Data Sheet'!I30 -> 3336.44 | ... K12: ='Data Sheet'!K30 -> 3971 | L12: =SUM(#REF!) -> #REF! | M12: =M10-M11*M10 -> #REF! | N12: =N10-N11*N10 -> #REF!
A13: EPS | B13: =IF('Data Sheet'!B93>0,B12/'Data Sheet'!B93,0) -> 2.4484212 | C13: =IF('Data Sheet'!C93>0,C12/'Data Sheet'!C93,0) -> 3.3146628 | D13: =IF('Data Sheet'!D93>0,D12/'Data Sheet'!D93,0) -> 8.9038007 | E13: =IF('Data Sheet'!E93>0,E12/'Data Sheet'!E93,0) -> 8.7111432 | F13: =IF('Data Sheet'!F93>0,F12/'Data Sheet'!F93,0) -> 3.7613872 | G13: =IF('Data Sheet'!G93>0,G12/'Data Sheet'!G93,0) -> 3.5282446 | H13: =IF('Data Sheet'!H93>0,H12/'Data Sheet'!H93,0) -> 5.4500673 | I13: =IF('Data Sheet'!I93>0,I12/'Data Sheet'!I93,0) -> 10.441711 | ... K13: =IF('Data Sheet'!K93>0,K12/'Data Sheet'!K93,0) -> 12.427628 | L13: =IF('Data Sheet'!$B6>0,'Profit & Loss'!L12/'Data Sheet'!$B6,0) -> #REF! | M13: =IF('Data Sheet'!$B6>0,'Profit & Loss'!M12/'Data Sheet'!$B6,0) -> #REF! | N13: =IF('Data Sheet'!$B6>0,'Profit & Loss'!N12/'Data Sheet'!$B6,0) -> #REF!
A14: Price to earning | B14: =IF(B15>0,B15/B13,"") -> 26.40477 | C14: =IF(C15>0,C15/C13,"") -> 27.257674 | D14: =IF(D15>0,D15/D13,"") -> 8.8726155 | E14: =IF(E15>0,E15/E13,"") -> 8.4719076 | F14: =IF(F15>0,F15/F13,"") -> 8.7334801 | G14: =IF(G15>0,G15/G13,"") -> 29.263844 | H14: =IF(H15>0,H15/H13,"") -> 43.78845 | I14: =IF(I15>0,I15/I13,"") -> 18.220194 | ... K14: =IF(K15>0,K15/K13,"") -> 30.20689 | L14: =IF(L13>0,L15/L13,0) -> #REF! | M14: =M25 -> #REF! | N14: =N25 -> #REF!
A15: Price | B15: ='Data Sheet'!B90 -> 64.65 | C15: ='Data Sheet'!C90 -> 90.35 | D15: ='Data Sheet'!D90 -> 79 | E15: ='Data Sheet'!E90 -> 73.8 | F15: ='Data Sheet'!F90 -> 32.85 | G15: ='Data Sheet'!G90 -> 103.25 | H15: ='Data Sheet'!H90 -> 238.65 | I15: ='Data Sheet'!I90 -> 190.25 | ... K15: ='Data Sheet'!K90 -> 375.4 | L15: ='Data Sheet'!B8 -> 367.4 | M15: =M13*M14 -> #REF! | N15: =N13*N14 -> #REF!
A17: RATIOS:
A18: Dividend Payout | B18: =IF('Data Sheet'!B30>0, 'Data Sheet'!B31/'Data Sheet'!B30, 0) -> 0.53098762 | C18: =IF('Data Sheet'!C30>0, 'Data Sheet'!C31/'Data Sheet'!C30, 0) -> 0.39222575 | D18: =IF('Data Sheet'!D30>0, 'Data Sheet'!D31/'Data Sheet'!D30, 0) -> 0.14601586 | E18: =IF('Data Sheet'!E30>0, 'Data Sheet'!E31/'Data Sheet'!E30, 0) -> 0.14924518 | F18: =IF('Data Sheet'!F30>0, 'Data Sheet'!F31/'Data Sheet'!F30, 0) -> 0.4121174 | G18: =IF('Data Sheet'!G30>0, 'Data Sheet'!G31/'Data Sheet'!G30, 0) -> 0.43935496 | H18: =IF('Data Sheet'!H30>0, 'Data Sheet'!H31/'Data Sheet'!H30, 0) -> 0.3211271 | I18: =IF('Data Sheet'!I30>0, 'Data Sheet'!I31/'Data Sheet'!I30, 0) -> 0.19155747 | ... K18: =IF('Data Sheet'!K30>0, 'Data Sheet'!K31/'Data Sheet'!K30, 0) -> 0.20118358
A19: OPM | B19: =IF(B6>0,B6/B4,0) -> 0.07137752 | C19: =IF(C6>0,C6/C4,0) -> 0.19839609 | D19: =IF(D6>0,D6/D4,0) -> 0.085499512 | E19: =IF(E6>0,E6/E4,0) -> 0.10273765 | F19: =IF(F6>0,F6/F4,0) -> 0.23355929 | G19: =IF(G6>0,G6/G4,0) -> 0.2116269 | H19: =IF(H6>0,H6/H4,0) -> 0.16421301 | I19: =IF(I6>0,I6/I4,0) -> 0.14022662 | ... L19: =IF(L6>0,L6/L4,0) -> #REF!
G22: TRENDS: | H22: 10 YEARS | I22: 7 YEARS | J22: 5 YEARS | K22: 3 YEARS | L22: RECENT | M22: BEST | N22: WORST
G23: Sales Growth | H23: =IF(B4=0,"",POWER($K4/B4,1/9)-1) -> 0.092658183 | I23: =IF(D4=0,"",POWER($K4/D4,1/7)-1) -> 0.13587363 | J23: =IF(F4=0,"",POWER($K4/F4,1/5)-1) -> 0.1757969 | K23: =IF(H4=0,"",POWER($K4/H4, 1/3)-1) -> 0.15212098 | L23: =IF(ISERROR(MAX(IF(J4=0,"",(K4-J4)/J4),IF(K4=0,"",(L4-K4)/K4))),"",MAX(IF(J4=0,"",(K4-J4)/J4),IF(K4=0,"",(L4-K4)/K4))) | M23: =MAX(K23:L23) -> 0.15212098 | N23: =MIN(H23:L23) -> 0.092658183
G24: OPM | H24: =IF(SUM(B4:$K$4)=0,"",SUMPRODUCT(B19:$K$19,B4:$K$4)/SUM(B4:$K$4)) -> 0.16062314 | I24: =IF(SUM(E4:$K$4)=0,"",SUMPRODUCT(E19:$K$19,E4:$K$4)/SUM(E4:$K$4)) -> 0.1720155 | J24: =IF(SUM(G4:$K$4)=0,"",SUMPRODUCT(G19:$K$19,G4:$K$4)/SUM(G4:$K$4)) -> 0.17309074 | K24: =IF(SUM(I4:$K$4)=0, "", SUMPRODUCT(I19:$K$19,I4:$K$4)/SUM(I4:$K$4)) -> 0.16825569 | L24: =L19 -> #REF! | M24: =MAX(K24:L24) -> #REF! | N24: =MIN(H24:L24) -> #REF!
G25: Price to Earning | H25: =IF(ISERROR(AVERAGEIF(B14:$L14,">0")),"",AVERAGEIF(B14:$L14,">0")) -> 23.529726 | I25: =IF(ISERROR(AVERAGEIF(E14:$L14,">0")),"",AVERAGEIF(E14:$L14,">0")) -> 24.680315 | J25: =IF(ISERROR(AVERAGEIF(G14:$L14,">0")),"",AVERAGEIF(G14:$L14,">0")) -> 31.111363 | K25: =IF(ISERROR(AVERAGEIF(I14:$L14,">0")),"",AVERAGEIF(I14:$L14,">0")) -> 27.501507 | L25: =L14 -> #REF! | M25: =MAX(K25:L25) -> #REF! | N25: =MIN(H25:L25) -> #REF!

Sheet HistoricalFS
B2: ="Historical Financial Statement - "& 'Data Sheet'!B1 -> Historical Financial Statement - TATA POWER COMPANY LTD
B3: Years | C3: ='Data Sheet'!B16 -> 42460 | D3: ='Data Sheet'!C16 -> 42825 | E3: ='Data Sheet'!D16 -> 43190 | F3: ='Data Sheet'!E16 -> 43555 | G3: ='Data Sheet'!F16 -> 43921 | H3: ='Data Sheet'!G16 -> 44286 | I3: ='Data Sheet'!H16 -> 44651 | J3: ='Data Sheet'!I16 -> 45016 | ... L3: ='Data Sheet'!K16 -> 45747 | M3: LTM
A5: # | B5: Income Statement
B6: Sales | C6: =IFERROR('Data Sheet'!B17,0) -> 29494.3 | D6: =IFERROR('Data Sheet'!C17,0) -> 27587.59 | E6: =IFERROR('Data Sheet'!D17,0) -> 26840.27 | F6: =IFERROR('Data Sheet'!E17,0) -> 29881.06 | G6: =IFERROR('Data Sheet'!F17,0) -> 29136.37 | H6: =IFERROR('Data Sheet'!G17,0) -> 32703.31 | I6: =IFERROR('Data Sheet'!H17,0) -> 42815.67 | J6: =IFERROR('Data Sheet'!I17,0) -> 55109.08 | ... L6: =IFERROR('Data Sheet'!K17,0) -> 65478.24 | M6: =IFERROR(SUM('Data Sheet'!H42:K42),0) -> 66066.92
B7: Sales Growth | C7: - | D7: =IFERROR(D6/C6-1,0) -> -0.064646728 | E7: =IFERROR(E6/D6-1,0) -> -0.027088992 | F7: =IFERROR(F6/E6-1,0) -> 0.11329208 | G7: =IFERROR(G6/F6-1,0) -> -0.024921807 | H7: =IFERROR(H6/G6-1,0) -> 0.12242225 | I7: =IFERROR(I6/H6-1,0) -> 0.30921518 | J7: =IFERROR(J6/I6-1,0) -> 0.28712408 | K7: =IFERROR(K6/J6-1,0) -> 0.1150413 | ... M7: =IFERROR(M6/L6-1,0) -> 0.0089904677
B9: COGS | C9: =IFERROR(SUM('Data Sheet'!B18,'Data Sheet'!B20:B22)-1*('Data Sheet'!B19),0) -> 21644.54 | D9: =IFERROR(SUM('Data Sheet'!C18,'Data Sheet'!C20:C22)-1*('Data Sheet'!C19),0) -> 21013.06 | E9: =IFERROR(SUM('Data Sheet'!D18,'Data Sheet'!D20:D22)-1*('Data Sheet'!D19),0) -> 19864.32 | F9: =IFERROR(SUM('Data Sheet'!E18,'Data Sheet'!E20:E22)-1*('Data Sheet'!E19),0) -> 22496.97 | G9: =IFERROR(SUM('Data Sheet'!F18,'Data Sheet'!F20:F22)-1*('Data Sheet'!F19),0) -> 20639.12 | H9: =IFERROR(SUM('Data Sheet'!G18,'Data Sheet'!G20:G22)-1*('Data Sheet'!G19),0) -> 24985.64 | I9: =IFERROR(SUM('Data Sheet'!H18,'Data Sheet'!H20:H22)-1*('Data Sheet'!H19),0) -> 34239.37 | J9: =IFERROR(SUM('Data Sheet'!I18,'Data Sheet'!I20:I22)-1*('Data Sheet'!I19),0) -> 45560.7 | ... M9: =IFERROR(SUM('Data Sheet'!L18,'Data Sheet'!L20:L22)-1*('Data Sheet'!L19),0) -> 0
B10: COGS % Sales | C10: =C9/C6 -> 0.73385502 | D10: =D9/D6 -> 0.76168524 | E10: =E9/E6 -> 0.7400939 | F10: =F9/F6 -> 0.75288393 | G10: =G9/G6 -> 0.70836278 | H10: =H9/H6 -> 0.76400951 | I10: =I9/I6 -> 0.7996925 | J10: =J9/J6 -> 0.82673672 | ... M10: =M9/M6 -> 0
B12: Gross Profit | C12: =C6-C9 -> 7849.76 | D12: =D6-D9 -> 6574.53 | E12: =E6-E9 -> 6975.95 | F12: =F6-F9 -> 7384.09 | G12: =G6-G9 -> 8497.25 | H12: =H6-H9 -> 7717.67 | I12: =I6-I9 -> 8576.3 | J12: =J6-J9 -> 9548.38 | ... M12: =M6-M9 -> 66066.92
B13: Gross Margin | C13: =C12/C6 -> 0.26614498 | D13: =D12/D6 -> 0.23831476 | E13: =E12/E6 -> 0.2599061 | F13: =F12/F6 -> 0.24711607 | G13: =G12/G6 -> 0.29163722 | H13: =H12/H6 -> 0.23599049 | I13: =I12/I6 -> 0.2003075 | J13: =J12/J6 -> 0.17326328 | ... M13: =M12/M6 -> 1
B15: Selling & General Expense | C15: =IFERROR(SUM('Data Sheet'!B23:B24),0) -> 5744.53 | D15: =IFERROR(SUM('Data Sheet'!C23:C24),0) -> 1101.26 | E15: =IFERROR(SUM('Data Sheet'!D23:D24),0) -> 4681.12 | F15: =IFERROR(SUM('Data Sheet'!E23:E24),0) -> 4314.18 | G15: =IFERROR(SUM('Data Sheet'!F23:F24),0) -> 1692.18 | H15: =IFERROR(SUM('Data Sheet'!G23:G24),0) -> 796.77 | I15: =IFERROR(SUM('Data Sheet'!H23:H24),0) -> 1545.41 | J15: =IFERROR(SUM('Data Sheet'!I23:I24),0) -> 1820.62 | ... L15: =IFERROR(SUM('Data Sheet'!K23:K24),0) -> 3434.43
B16: S&G % Expenses | C16: =C15/C6 -> 0.19476746 | D16: =D15/D6 -> 0.039918674 | E16: =E15/E6 -> 0.17440659 | F16: =F15/F6 -> 0.14437841 | G16: =G15/G6 -> 0.058077928 | H16: =H15/H6 -> 0.024363589 | I16: =I15/I6 -> 0.036094495 | J16: =J15/J6 -> 0.033036661 | ... M16: =M15/M6 -> 0
B18: EBIDTA | C18: =C12-C15 -> 2105.23 | D18: =D12-D15 -> 5473.27 | E18: =E12-E15 -> 2294.83 | F18: =F12-F15 -> 3069.91 | G18: =G12-G15 -> 6805.07 | H18: =H12-H15 -> 6920.9 | I18: =I12-I15 -> 7030.89 | J18: =J12-J15 -> 7727.76 | ... L18: =L12-L15 -> 12165.59 | M18: =IFERROR(SUM('Data Sheet'!H45:K47),0) -> 15816.95
B19: EBIDTA Margins | C19: =C18/C6 -> 0.07137752 | D19: =D18/D6 -> 0.19839609 | E19: =E18/E6 -> 0.085499512 | F19: =F18/F6 -> 0.10273765 | G19: =G18/G6 -> 0.23355929 | H19: =H18/H6 -> 0.2116269 | I19: =I18/I6 -> 0.16421301 | J19: =J18/J6 -> 0.14022662 | ... M19: =M18/M6 -> 0.23940801
B21: Interest | C21: =IFERROR('Data Sheet'!B27,0) -> 3235.81 | D21: =IFERROR('Data Sheet'!C27,0) -> 3364.96 | E21: =IFERROR('Data Sheet'!D27,0) -> 3761.48 | F21: =IFERROR('Data Sheet'!E27,0) -> 4170 | G21: =IFERROR('Data Sheet'!F27,0) -> 4493.73 | H21: =IFERROR('Data Sheet'!G27,0) -> 4010.39 | I21: =IFERROR('Data Sheet'!H27,0) -> 3859.02 | J21: =IFERROR('Data Sheet'!I27,0) -> 4371.65 | ... L21: =IFERROR('Data Sheet'!K27,0) -> 4702.44 | M21: =IFERROR(SUM('Data Sheet'!H46:K46),0) -> 4980.98
B22: Interest % Sales | C22: =C21/C6 -> 0.10970967 | D22: =D21/D6 -> 0.12197368 | E22: =E21/E6 -> 0.14014315 | F22: =F21/F6 -> 0.13955328 | G22: =G21/G6 -> 0.15423095 | H22: =H21/H6 -> 0.12262948 | I22: =I21/I6 -> 0.09013102 | J22: =J21/J6 -> 0.079327218 | ... M22: =M21/M6 -> 0.07539295
B24: Depreciation | C24: =IFERROR('Data Sheet'!B26,0) -> 1648.73 | D24: =IFERROR('Data Sheet'!C26,0) -> 1955.59 | E24: =IFERROR('Data Sheet'!D26,0) -> 2346.17 | F24: =IFERROR('Data Sheet'!E26,0) -> 2393.13 | G24: =IFERROR('Data Sheet'!F26,0) -> 2633.56 | H24: =IFERROR('Data Sheet'!G26,0) -> 2744.94 | I24: =IFERROR('Data Sheet'!H26,0) -> 3122.2 | J24: =IFERROR('Data Sheet'!I26,0) -> 3439.2 | ... L24: =IFERROR('Data Sheet'!K26,0) -> 4116.86 | M24: =IFERROR(SUM('Data Sheet'!H45:K45),0) -> 4480.23
B25: Depreciation % Sales | C25: =C24/C6 -> 0.055899954 | D25: =D24/D6 -> 0.070886583 | E25: =E24/E6 -> 0.08741231 | F25: =F24/F6 -> 0.080088524 | G25: =G24/G6 -> 0.090387375 | H25: =H24/H6 -> 0.083934623 | I25: =I24/I6 -> 0.0729219 | J25: =J24/J6 -> 0.062407139 | ... M25: =M24/M6 -> 0.067813514
B27: Earning Before Tax | C27: =IFERROR(C18-SUM(C24,C21),0) -> -2779.31 | D27: =IFERROR(D18-SUM(D24,D21),0) -> 152.72 | E27: =IFERROR(E18-SUM(E24,E21),0) -> -3812.82 | F27: =IFERROR(F18-SUM(F24,F21),0) -> -3493.22 | G27: =IFERROR(G18-SUM(G24,G21),0) -> -322.22 | H27: =IFERROR(H18-SUM(H24,H21),0) -> 165.57 | I27: =IFERROR(I18-SUM(I24,I21),0) -> 49.67 | J27: =IFERROR(J18-SUM(J24,J21),0) -> -83.09 | ... M27: =IFERROR(M18-SUM(M24,M21),0) -> 6355.74
B28: EBT % Sales | C28: =C27/C6 -> -0.094232106 | D28: =D27/D6 -> 0.0055358224 | E28: =E27/E6 -> -0.14205595 | F28: =F27/F6 -> -0.11690415 | G28: =G27/G6 -> -0.01105903 | H28: =H27/H6 -> 0.0050627903 | I28: =I27/I6 -> 0.0011600893 | J28: =J27/J6 -> -0.001507737 | ... M28: =M27/M6 -> 0.096201548
B30: Tax | C30: =IFERROR('Data Sheet'!B29,0) -> 680.31 | D30: =IFERROR('Data Sheet'!C29,0) -> 350.46 | E30: =IFERROR('Data Sheet'!D29,0) -> 161.97 | F30: =IFERROR('Data Sheet'!E29,0) -> 1087.59 | G30: =IFERROR('Data Sheet'!F29,0) -> 641.49 | H30: =IFERROR('Data Sheet'!G29,0) -> 501.88 | I30: =IFERROR('Data Sheet'!H29,0) -> 379.56 | J30: =IFERROR('Data Sheet'!I29,0) -> 1647.33 | ... L30: =IFERROR('Data Sheet'!K29,0) -> 1544.25 | M30: =IFERROR(SUM('Data Sheet'!H48:K48),0) -> 1354.4
B31: Effective Tax Rate | C31: =C30/C27 -> -0.24477658 | D31: =D30/D27 -> 2.2947878 | E31: =E30/E27 -> -0.042480369 | F31: =F30/F27 -> -0.31134312 | G31: =G30/G27 -> -1.9908448 | H31: =H30/H27 -> 3.0312255 | I31: =I30/I27 -> 7.6416348 | J31: =J30/J27 -> -19.825851 | ... M31: =M30/M27 -> 0.21309871
B33: Net Profit | C33: =IFERROR(C27-C30,0) -> -3459.62 | D33: =IFERROR(D27-D30,0) -> -197.74 | E33: =IFERROR(E27-E30,0) -> -3974.79 | F33: =IFERROR(F27-F30,0) -> -4580.81 | G33: =IFERROR(G27-G30,0) -> -963.71 | H33: =IFERROR(H27-H30,0) -> -336.31 | I33: =IFERROR(I27-I30,0) -> -329.89 | J33: =IFERROR(J27-J30,0) -> -1730.42 | ... M33: =IFERROR(M27-M30,0) -> 5001.34
B34: Net Margins | C34: =C33/C6 -> -0.11729792 | D34: =D33/D6 -> -0.0071677156 | E34: =E33/E6 -> -0.14809054 | F34: =F33/F6 -> -0.15330146 | G34: =G33/G6 -> -0.033075843 | H34: =H33/H6 -> -0.010283669 | I34: =I33/I6 -> -0.0077048894 | J34: =J33/J6 -> -0.031399907 | ... M34: =M33/M6 -> 0.075701122
B36: No of Equity Shares | C36: =IFERROR('Data Sheet'!B93,0) -> 270.46 | D36: =IFERROR('Data Sheet'!C93,0) -> 270.48 | E36: =IFERROR('Data Sheet'!D93,0) -> 270.48 | F36: =IFERROR('Data Sheet'!E93,0) -> 270.48 | G36: =IFERROR('Data Sheet'!F93,0) -> 270.48 | H36: =IFERROR('Data Sheet'!G93,0) -> 319.53 | I36: =IFERROR('Data Sheet'!H93,0) -> 319.53 | J36: =IFERROR('Data Sheet'!I93,0) -> 319.53 | ... M36: =IFERROR('Data Sheet'!L93,0) -> 0
B38: Earning per Share | C38: =IFERROR(C33/C36,0) -> -12.791614 | D38: =IFERROR(D33/D36,0) -> -0.73107069 | E38: =IFERROR(E33/E36,0) -> -14.695319 | F38: =IFERROR(F33/F36,0) -> -16.935855 | G38: =IFERROR(G33/G36,0) -> -3.5629621 | H38: =IFERROR(H33/H36,0) -> -1.0525146 | I38: =IFERROR(I33/I36,0) -> -1.0324226 | J38: =IFERROR(J33/J36,0) -> -5.4155165 | ... M38: =IFERROR(M33/M36,0) -> 0
B39: EPS Growth % | D39: =IFERROR(D38/C38-1,0) -> -0.94284766 | E39: =IFERROR(E38/D38-1,0) -> 19.101092 | F39: =IFERROR(F38/E38-1,0) -> 0.15246592 | G39: =IFERROR(G38/F38-1,0) -> -0.78962018 | H39: =IFERROR(H38/G38-1,0) -> -0.70459562 | I39: =IFERROR(I38/H38-1,0) -> -0.01908953 | J39: =IFERROR(J38/I38-1,0) -> 4.2454455 | K39: =IFERROR(K38/J38-1,0) -> -1.4991678 | ... M39: =IFERROR(M38/L38-1,0) -> -1
B41: Dividend per Share | C41: =IFERROR('Data Sheet'!B31/HistoricalFS!C36,0) -> 1.3000813 | D41: =IFERROR('Data Sheet'!C31/HistoricalFS!D36,0) -> 1.3000961 | E41: =IFERROR('Data Sheet'!D31/HistoricalFS!E36,0) -> 1.3000961 | F41: =IFERROR('Data Sheet'!E31/HistoricalFS!F36,0) -> 1.3000961 | G41: =IFERROR('Data Sheet'!F31/HistoricalFS!G36,0) -> 1.5501331 | H41: =IFERROR('Data Sheet'!G31/HistoricalFS!H36,0) -> 1.5501518 | I41: =IFERROR('Data Sheet'!H31/HistoricalFS!I36,0) -> 1.7501643 | J41: =IFERROR('Data Sheet'!I31/HistoricalFS!J36,0) -> 2.0001878 | ... M41: =IFERROR('Data Sheet'!L31/HistoricalFS!M36,0) -> 0
B42: Dividend payout ratio | C42: =IFERROR(C41/C38,0) -> -0.10163544 | D42: =IFERROR(D41/D38,0) -> -1.7783453 | E42: =IFERROR(E41/E38,0) -> -0.088470083 | F42: =IFERROR(F41/F38,0) -> -0.076765899 | G42: =IFERROR(G41/G38,0) -> -0.43506864 | H42: =IFERROR(H41/H38,0) -> -1.4728078 | I42: =IFERROR(I41/I38,0) -> -1.6952014 | J42: =IFERROR(J41/J38,0) -> -0.36934386 | ... M42: =IFERROR(M41/M38,0) -> 0
B44: Retained Earnings | C44: =IFERROR(IF(C38>C41,1-C42,0),0) -> 0 | D44: =IFERROR(IF(D38>D41,1-D42,0),0) -> 0 | E44: =IFERROR(IF(E38>E41,1-E42,0),0) -> 0 | F44: =IFERROR(IF(F38>F41,1-F42,0),0) -> 0 | G44: =IFERROR(IF(G38>G41,1-G42,0),0) -> 0 | H44: =IFERROR(IF(H38>H41,1-H42,0),0) -> 0 | I44: =IFERROR(IF(I38>I41,1-I42,0),0) -> 0 | J44: =IFERROR(IF(J38>J41,1-J42,0),0) -> 0 | ... M44: =IFERROR(IF(M38>M41,1-M42,0),0) -> 0
A46: # | B46: Balance Sheet
B47: Equity Share Capital | C47: =IFERROR('Data Sheet'!B57,0) -> 270.48 | D47: =IFERROR('Data Sheet'!C57,0) -> 270.5 | E47: =IFERROR('Data Sheet'!D57,0) -> 270.5 | F47: =IFERROR('Data Sheet'!E57,0) -> 270.5 | G47: =IFERROR('Data Sheet'!F57,0) -> 270.5 | H47: =IFERROR('Data Sheet'!G57,0) -> 319.56 | I47: =IFERROR('Data Sheet'!H57,0) -> 319.56 | J47: =IFERROR('Data Sheet'!I57,0) -> 319.56 | ... L47: =IFERROR('Data Sheet'!K57,0) -> 319.56
B48: Reserves | C48: =IFERROR('Data Sheet'!B58,0) -> 11362.9 | D48: =IFERROR('Data Sheet'!C58,0) -> 12944.05 | E48: =IFERROR('Data Sheet'!D58,0) -> 16129.38 | F48: =IFERROR('Data Sheet'!E58,0) -> 18035.01 | G48: =IFERROR('Data Sheet'!F58,0) -> 19295.52 | H48: =IFERROR('Data Sheet'!G58,0) -> 22002.7 | I48: =IFERROR('Data Sheet'!H58,0) -> 22122 | J48: =IFERROR('Data Sheet'!I58,0) -> 28467.87 | ... L48: =IFERROR('Data Sheet'!K58,0) -> 35521.11
B49: Borrowings | C49: =IFERROR('Data Sheet'!B59,0) -> 38848.59 | D49: =IFERROR('Data Sheet'!C59,0) -> 48815.41 | E49: =IFERROR('Data Sheet'!D59,0) -> 48589.24 | F49: =IFERROR('Data Sheet'!E59,0) -> 48506.04 | G49: =IFERROR('Data Sheet'!F59,0) -> 51936.15 | H49: =IFERROR('Data Sheet'!G59,0) -> 46707.95 | I49: =IFERROR('Data Sheet'!H59,0) -> 51195.12 | J49: =IFERROR('Data Sheet'!I59,0) -> 52923 | ... L49: =IFERROR('Data Sheet'!K59,0) -> 62865.8
B50: Other Liabilities | C50: =IFERROR('Data Sheet'!B60,0) -> 19574.54 | D50: =IFERROR('Data Sheet'!C60,0) -> 20799.3 | E50: =IFERROR('Data Sheet'!D60,0) -> 16902.68 | F50: =IFERROR('Data Sheet'!E60,0) -> 17261.89 | G50: =IFERROR('Data Sheet'!F60,0) -> 18171.74 | H50: =IFERROR('Data Sheet'!G60,0) -> 29624.63 | I50: =IFERROR('Data Sheet'!H60,0) -> 38913.31 | J50: =IFERROR('Data Sheet'!I60,0) -> 46385.71 | ... L50: =IFERROR('Data Sheet'!K60,0) -> 57486.83
B51: Total Liabilities | C51: =IFERROR('Data Sheet'!B61,0) -> 70056.51 | D51: =IFERROR('Data Sheet'!C61,0) -> 82829.26 | E51: =IFERROR('Data Sheet'!D61,0) -> 81891.8 | F51: =IFERROR('Data Sheet'!E61,0) -> 84073.44 | G51: =IFERROR('Data Sheet'!F61,0) -> 89673.91 | H51: =IFERROR('Data Sheet'!G61,0) -> 98654.84 | I51: =IFERROR('Data Sheet'!H61,0) -> 112549.99 | J51: =IFERROR('Data Sheet'!I61,0) -> 128096.14 | ... L51: =IFERROR('Data Sheet'!K61,0) -> 156193.3
B53: Fixed Assets Net Block | C53: =IFERROR('Data Sheet'!B62,0) -> 36413.72 | D53: =IFERROR('Data Sheet'!C62,0) -> 46594.79 | E53: =IFERROR('Data Sheet'!D62,0) -> 44656.26 | F53: =IFERROR('Data Sheet'!E62,0) -> 44304.89 | G53: =IFERROR('Data Sheet'!F62,0) -> 47666.36 | H53: =IFERROR('Data Sheet'!G62,0) -> 52179.15 | I53: =IFERROR('Data Sheet'!H62,0) -> 57389.44 | J53: =IFERROR('Data Sheet'!I62,0) -> 61746.66 | ... L53: =IFERROR('Data Sheet'!K62,0) -> 78374.43
B54: Capital Work in Progress | C54: =IFERROR('Data Sheet'!B63,0) -> 1344.91 | D54: =IFERROR('Data Sheet'!C63,0) -> 2177.92 | E54: =IFERROR('Data Sheet'!D63,0) -> 1652.6 | F54: =IFERROR('Data Sheet'!E63,0) -> 2575.7 | G54: =IFERROR('Data Sheet'!F63,0) -> 1611.52 | H54: =IFERROR('Data Sheet'!G63,0) -> 3270.26 | I54: =IFERROR('Data Sheet'!H63,0) -> 4635.1 | J54: =IFERROR('Data Sheet'!I63,0) -> 5376.36 | ... L54: =IFERROR('Data Sheet'!K63,0) -> 12678.87
B55: Investments | C55: =IFERROR('Data Sheet'!B64,0) -> 11785.35 | D55: =IFERROR('Data Sheet'!C64,0) -> 11873.01 | E55: =IFERROR('Data Sheet'!D64,0) -> 12428.93 | F55: =IFERROR('Data Sheet'!E64,0) -> 13541.87 | G55: =IFERROR('Data Sheet'!F64,0) -> 14534.84 | H55: =IFERROR('Data Sheet'!G64,0) -> 13149.05 | I55: =IFERROR('Data Sheet'!H64,0) -> 14160.33 | J55: =IFERROR('Data Sheet'!I64,0) -> 16669.69 | ... L55: =IFERROR('Data Sheet'!K64,0) -> 16316.39
B56: Other Assets | C56: =IFERROR('Data Sheet'!B65-SUM('Data Sheet'!B67:B69),0) -> 14935.73 | D56: =IFERROR('Data Sheet'!C65-SUM('Data Sheet'!C67:C69),0) -> 15797.56 | E56: =IFERROR('Data Sheet'!D65-SUM('Data Sheet'!D67:D69),0) -> 17556.22 | F56: =IFERROR('Data Sheet'!E65-SUM('Data Sheet'!E67:E69),0) -> 16711.85 | G56: =IFERROR('Data Sheet'!F65-SUM('Data Sheet'!F67:F69),0) -> 17588.76 | H56: =IFERROR('Data Sheet'!G65-SUM('Data Sheet'!G67:G69),0) -> 17100.01 | I56: =IFERROR('Data Sheet'!H65-SUM('Data Sheet'!H67:H69),0) -> 19513.16 | J56: =IFERROR('Data Sheet'!I65-SUM('Data Sheet'!I67:I69),0) -> 22201.87 | ... L56: =IFERROR('Data Sheet'!K65-SUM('Data Sheet'!K67:K69),0) -> 26791.03
B57: Total Non Current Assets | C57: =IFERROR(SUM(C53:C56),0) -> 64479.71 | D57: =IFERROR(SUM(D53:D56),0) -> 76443.28 | E57: =IFERROR(SUM(E53:E56),0) -> 76294.01 | F57: =IFERROR(SUM(F53:F56),0) -> 77134.31 | G57: =IFERROR(SUM(G53:G56),0) -> 81401.48 | H57: =IFERROR(SUM(H53:H56),0) -> 85698.47 | I57: =IFERROR(SUM(I53:I56),0) -> 95698.03 | J57: =IFERROR(SUM(J53:J56),0) -> 105994.58 | ... L57: =IFERROR(SUM(L53:L56),0) -> 134160.72
...

Sheet Ratio Analysis
B2: ="Ratio Analysis - "& 'Data Sheet'!B1 -> Ratio Analysis - TATA POWER COMPANY LTD
B3: Years | C3: ='Data Sheet'!B16 -> 42460 | D3: ='Data Sheet'!C16 -> 42825 | E3: ='Data Sheet'!D16 -> 43190 | F3: ='Data Sheet'!E16 -> 43555 | G3: ='Data Sheet'!F16 -> 43921 | H3: ='Data Sheet'!G16 -> 44286 | I3: ='Data Sheet'!H16 -> 44651 | J3: ='Data Sheet'!I16 -> 45016 | ... L3: ='Data Sheet'!K16 -> 45747 | M3: Trend | N3: Mean | O3: Median
B5: Sales Growth | C5: =IFERROR(HistoricalFS!C7,0) -> - | D5: =IFERROR(HistoricalFS!D7,0) -> -0.064646728 | E5: =IFERROR(HistoricalFS!E7,0) -> -0.027088992 | F5: =IFERROR(HistoricalFS!F7,0) -> 0.11329208 | G5: =IFERROR(HistoricalFS!G7,0) -> -0.024921807 | H5: =IFERROR(HistoricalFS!H7,0) -> 0.12242225 | I5: =IFERROR(HistoricalFS!I7,0) -> 0.30921518 | J5: =IFERROR(HistoricalFS!J7,0) -> 0.28712408 | ... L5: =IFERROR(HistoricalFS!L7,0) -> 0.065572207 | N5: =IFERROR(AVERAGE(D5:L5),0) -> 0.099556619 | O5: =IFERROR(MEDIAN(C5:L5),0) -> 0.11329208
B6: EBITDA Growth | D6: =IFERROR(HistoricalFS!D18/HistoricalFS!C18-1,0) -> 1.5998442 | E6: =IFERROR(HistoricalFS!E18/HistoricalFS!D18-1,0) -> -0.58072048 | F6: =IFERROR(HistoricalFS!F18/HistoricalFS!E18-1,0) -> 0.33775051 | G6: =IFERROR(HistoricalFS!G18/HistoricalFS!F18-1,0) -> 1.2167002 | H6: =IFERROR(HistoricalFS!H18/HistoricalFS!G18-1,0) -> 0.017021133 | I6: =IFERROR(HistoricalFS!I18/HistoricalFS!H18-1,0) -> 0.015892442 | J6: =IFERROR(HistoricalFS!J18/HistoricalFS!I18-1,0) -> 0.099115475 | K6: =IFERROR(HistoricalFS!K18/HistoricalFS!J18-1,0) -> 0.38918393 | L6: =IFERROR(HistoricalFS!L18/HistoricalFS!K18-1,0) -> 0.13323453 | N6: =IFERROR(AVERAGE(D6:L6),0) -> 0.3586691 | O6: =IFERROR(MEDIAN(C6:L6),0) -> 0.13323453
B7: EBIT Growth | D7: =IFERROR(HistoricalFS!D27/HistoricalFS!C27-1,0) -> -1.0549489 | E7: =IFERROR(HistoricalFS!E27/HistoricalFS!D27-1,0) -> -25.966082 | F7: =IFERROR(HistoricalFS!F27/HistoricalFS!E27-1,0) -> -0.083822473 | G7: =IFERROR(HistoricalFS!G27/HistoricalFS!F27-1,0) -> -0.90775846 | H7: =IFERROR(HistoricalFS!H27/HistoricalFS!G27-1,0) -> -1.5138415 | I7: =IFERROR(HistoricalFS!I27/HistoricalFS!H27-1,0) -> -0.70000604 | J7: =IFERROR(HistoricalFS!J27/HistoricalFS!I27-1,0) -> -2.6728407 | K7: =IFERROR(HistoricalFS!K27/HistoricalFS!J27-1,0) -> -28.869659 | L7: =IFERROR(HistoricalFS!L27/HistoricalFS!K27-1,0) -> 0.44505094 | N7: =IFERROR(AVERAGE(D7:L7),0) -> -6.8137676 | O7: =IFERROR(MEDIAN(C7:L7),0) -> -1.0549489
B8: Net Profit Growth | D8: =IFERROR(HistoricalFS!D33/HistoricalFS!C33-1,0) -> -0.94284343 | E8: =IFERROR(HistoricalFS!E33/HistoricalFS!D33-1,0) -> 19.101092 | F8: =IFERROR(HistoricalFS!F33/HistoricalFS!E33-1,0) -> 0.15246592 | G8: =IFERROR(HistoricalFS!G33/HistoricalFS!F33-1,0) -> -0.78962018 | H8: =IFERROR(HistoricalFS!H33/HistoricalFS!G33-1,0) -> -0.65102572 | I8: =IFERROR(HistoricalFS!I33/HistoricalFS!H33-1,0) -> -0.01908953 | J8: =IFERROR(HistoricalFS!J33/HistoricalFS!I33-1,0) -> 4.2454455 | K8: =IFERROR(HistoricalFS!K33/HistoricalFS!J33-1,0) -> -1.4991678 | L8: =IFERROR(HistoricalFS!L33/HistoricalFS!K33-1,0) -> 1.0862498 | N8: =IFERROR(AVERAGE(D8:L8),0) -> 2.2981674 | O8: =IFERROR(MEDIAN(C8:L8),0) -> -0.01908953
B9: Dividend Growth | D9: =IFERROR(HistoricalFS!D41/HistoricalFS!C41-1,0) -> 1.137045e-05 | E9: =IFERROR(HistoricalFS!E41/HistoricalFS!D41-1,0) -> 0 | F9: =IFERROR(HistoricalFS!F41/HistoricalFS!E41-1,0) -> 0 | G9: =IFERROR(HistoricalFS!G41/HistoricalFS!F41-1,0) -> 0.19232191 | H9: =IFERROR(HistoricalFS!H41/HistoricalFS!G41-1,0) -> 1.2056202e-05 | I9: =IFERROR(HistoricalFS!I41/HistoricalFS!H41-1,0) -> 0.1290277 | J9: =IFERROR(HistoricalFS!J41/HistoricalFS!I41-1,0) -> 0.14285714 | K9: =IFERROR(HistoricalFS!K41/HistoricalFS!J41-1,0) -> 0 | L9: =IFERROR(HistoricalFS!L41/HistoricalFS!K41-1,0) -> 0.25 | N9: =IFERROR(AVERAGE(D9:L9),0) -> 0.079358909 | O9: =IFERROR(MEDIAN(C9:L9),0) -> 1.2056202e-05
B11: Gross Margin | C11: =IFERROR(HistoricalFS!C13,0) -> 0.26614498 | D11: =IFERROR(HistoricalFS!D13,0) -> 0.23831476 | E11: =IFERROR(HistoricalFS!E13,0) -> 0.2599061 | F11: =IFERROR(HistoricalFS!F13,0) -> 0.24711607 | G11: =IFERROR(HistoricalFS!G13,0) -> 0.29163722 | H11: =IFERROR(HistoricalFS!H13,0) -> 0.23599049 | I11: =IFERROR(HistoricalFS!I13,0) -> 0.2003075 | J11: =IFERROR(HistoricalFS!J13,0) -> 0.17326328 | ... L11: =IFERROR(HistoricalFS!L13,0) -> 0.23824739 | N11: =IFERROR(AVERAGE(C11:L11),0) -> 0.23523656 | O11: =IFERROR(MEDIAN(C11:L11),0) -> 0.23828108
B12: EBIDTA Margin | C12: =IFERROR(HistoricalFS!C19,0) -> 0.07137752 | D12: =IFERROR(HistoricalFS!D19,0) -> 0.19839609 | E12: =IFERROR(HistoricalFS!E19,0) -> 0.085499512 | F12: =IFERROR(HistoricalFS!F19,0) -> 0.10273765 | G12: =IFERROR(HistoricalFS!G19,0) -> 0.23355929 | H12: =IFERROR(HistoricalFS!H19,0) -> 0.2116269 | I12: =IFERROR(HistoricalFS!I19,0) -> 0.16421301 | J12: =IFERROR(HistoricalFS!J19,0) -> 0.14022662 | ... L12: =IFERROR(HistoricalFS!L19,0) -> 0.18579592 | N12: =IFERROR(AVERAGE(C12:L12),0) -> 0.15681351 | O12: =IFERROR(MEDIAN(C12:L12),0) -> 0.16945778
B13: EBIT Margin | C13: =IFERROR((HistoricalFS!C18-HistoricalFS!C24)/HistoricalFS!C6,0) -> 0.015477567 | D13: =IFERROR((HistoricalFS!D18-HistoricalFS!D24)/HistoricalFS!D6,0) -> 0.12750951 | E13: =IFERROR((HistoricalFS!E18-HistoricalFS!E24)/HistoricalFS!E6,0) -> -0.0019127974 | F13: =IFERROR((HistoricalFS!F18-HistoricalFS!F24)/HistoricalFS!F6,0) -> 0.02264913 | G13: =IFERROR((HistoricalFS!G18-HistoricalFS!G24)/HistoricalFS!G6,0) -> 0.14317192 | H13: =IFERROR((HistoricalFS!H18-HistoricalFS!H24)/HistoricalFS!H6,0) -> 0.12769227 | I13: =IFERROR((HistoricalFS!I18-HistoricalFS!I24)/HistoricalFS!I6,0) -> 0.091291109 | J13: =IFERROR((HistoricalFS!J18-HistoricalFS!J24)/HistoricalFS!J6,0) -> 0.077819481 | ... L13: =IFERROR((HistoricalFS!L18-HistoricalFS!L24)/HistoricalFS!L6,0) -> 0.12292221 | N13: =IFERROR(AVERAGE(C13:L13),0) -> 0.083970477 | O13: =IFERROR(MEDIAN(C13:L13),0) -> 0.10218774
B14: EBT Margin | C14: =IFERROR(HistoricalFS!C28,0) -> -0.094232106 | D14: =IFERROR(HistoricalFS!D28,0) -> 0.0055358224 | E14: =IFERROR(HistoricalFS!E28,0) -> -0.14205595 | F14: =IFERROR(HistoricalFS!F28,0) -> -0.11690415 | G14: =IFERROR(HistoricalFS!G28,0) -> -0.01105903 | H14: =IFERROR(HistoricalFS!H28,0) -> 0.0050627903 | I14: =IFERROR(HistoricalFS!I28,0) -> 0.0011600893 | J14: =IFERROR(HistoricalFS!J28,0) -> -0.001507737 | ... L14: =IFERROR(HistoricalFS!L28,0) -> 0.051105375 | N14: =IFERROR(AVERAGE(C14:L14),0) -> -0.026521009 | O14: =IFERROR(MEDIAN(C14:L14),0) -> -0.00017382387
B15: Net Profit Margin | C15: =IFERROR(HistoricalFS!C34,0) -> -0.11729792 | D15: =IFERROR(HistoricalFS!D34,0) -> -0.0071677156 | E15: =IFERROR(HistoricalFS!E34,0) -> -0.14809054 | F15: =IFERROR(HistoricalFS!F34,0) -> -0.15330146 | G15: =IFERROR(HistoricalFS!G34,0) -> -0.033075843 | H15: =IFERROR(HistoricalFS!H34,0) -> -0.010283669 | I15: =IFERROR(HistoricalFS!I34,0) -> -0.0077048894 | J15: =IFERROR(HistoricalFS!J34,0) -> -0.031399907 | ... L15: =IFERROR(HistoricalFS!L34,0) -> 0.027521204 | N15: =IFERROR(AVERAGE(C15:L15),0) -> -0.046674401 | O15: =IFERROR(MEDIAN(C15:L15),0) -> -0.020841788
B17: Sales Expense% Sales | C17: =IFERROR(HistoricalFS!C16,0) -> 0.19476746 | D17: =IFERROR(HistoricalFS!D16,0) -> 0.039918674 | E17: =IFERROR(HistoricalFS!E16,0) -> 0.17440659 | F17: =IFERROR(HistoricalFS!F16,0) -> 0.14437841 | G17: =IFERROR(HistoricalFS!G16,0) -> 0.058077928 | H17: =IFERROR(HistoricalFS!H16,0) -> 0.024363589 | I17: =IFERROR(HistoricalFS!I16,0) -> 0.036094495 | J17: =IFERROR(HistoricalFS!J16,0) -> 0.033036661 | ... L17: =IFERROR(HistoricalFS!L16,0) -> 0.052451471 | N17: =IFERROR(AVERAGE(C17:L17),0) -> 0.078423051 | O17: =IFERROR(MEDIAN(C17:L17),0) -> 0.046185072
B18: Depreciation% Sales | C18: =IFERROR(HistoricalFS!C25,0) -> 0.055899954 | D18: =IFERROR(HistoricalFS!D25,0) -> 0.070886583 | E18: =IFERROR(HistoricalFS!E25,0) -> 0.08741231 | F18: =IFERROR(HistoricalFS!F25,0) -> 0.080088524 | G18: =IFERROR(HistoricalFS!G25,0) -> 0.090387375 | H18: =IFERROR(HistoricalFS!H25,0) -> 0.083934623 | I18: =IFERROR(HistoricalFS!I25,0) -> 0.0729219 | J18: =IFERROR(HistoricalFS!J25,0) -> 0.062407139 | ... L18: =IFERROR(HistoricalFS!L25,0) -> 0.062873712 | N18: =IFERROR(AVERAGE(C18:L18),0) -> 0.072843031 | O18: =IFERROR(MEDIAN(C18:L18),0) -> 0.071904242
B19: Operating% Sales | C19: =C13 -> 0.015477567 | D19: =D13 -> 0.12750951 | E19: =E13 -> -0.0019127974 | F19: =F13 -> 0.02264913 | G19: =G13 -> 0.14317192 | H19: =H13 -> 0.12769227 | I19: =I13 -> 0.091291109 | J19: =J13 -> 0.077819481 | ... L19: =L13 -> 0.12292221 | N19: =IFERROR(AVERAGE(C19:L19),0) -> 0.083970477 | O19: =IFERROR(MEDIAN(C19:L19),0) -> 0.10218774
B21: Return on Capital Employed | C21: =IFERROR((HistoricalFS!C18-HistoricalFS!C24)/SUM(HistoricalFS!C47:C49),0) -> 0.0090428325 | D21: =IFERROR((HistoricalFS!D18-HistoricalFS!D24)/SUM(HistoricalFS!D47:D49),0) -> 0.056709371 | E21: =IFERROR((HistoricalFS!E18-HistoricalFS!E24)/SUM(HistoricalFS!E47:E49),0) -> -0.00078997838 | F21: =IFERROR((HistoricalFS!F18-HistoricalFS!F24)/SUM(HistoricalFS!F47:F49),0) -> 0.010129686 | G21: =IFERROR((HistoricalFS!G18-HistoricalFS!G24)/SUM(HistoricalFS!G47:G49),0) -> 0.058341027 | H21: =IFERROR((HistoricalFS!H18-HistoricalFS!H24)/SUM(HistoricalFS!H47:H49),0) -> 0.060494673 | I21: =IFERROR((HistoricalFS!I18-HistoricalFS!I24)/SUM(HistoricalFS!I47:I49),0) -> 0.053080747 | J21: =IFERROR((HistoricalFS!J18-HistoricalFS!J24)/SUM(HistoricalFS!J47:J49),0) -> 0.052484854 | ... L21: =IFERROR((HistoricalFS!L18-HistoricalFS!L24)/SUM(HistoricalFS!L47:L49),0) -> 0.081542071 | N21: =IFERROR(AVERAGE(C21:L21),0) -> 0.046179455 | O21: =IFERROR(MEDIAN(C21:L21),0) -> 0.054895059
B22: Retained Earning% | C22: =IFERROR(HistoricalFS!C44,0) -> 0 | D22: =IFERROR(HistoricalFS!D44,0) -> 0 | E22: =IFERROR(HistoricalFS!E44,0) -> 0 | F22: =IFERROR(HistoricalFS!F44,0) -> 0 | G22: =IFERROR(HistoricalFS!G44,0) -> 0 | H22: =IFERROR(HistoricalFS!H44,0) -> 0 | I22: =IFERROR(HistoricalFS!I44,0) -> 0 | J22: =IFERROR(HistoricalFS!J44,0) -> 0 | ... L22: =IFERROR(HistoricalFS!L44,0) -> 0.55666911 | N22: =IFERROR(AVERAGE(C22:L22),0) -> 0.081674992 | O22: =IFERROR(MEDIAN(C22:L22),0) -> 0
B23: Return on Equity% | C23: =IFERROR(HistoricalFS!C33/SUM(HistoricalFS!C47:C48),0) -> -0.29738735 | D23: =IFERROR(HistoricalFS!D33/SUM(HistoricalFS!D47:D48),0) -> -0.014963809 | E23: =IFERROR(HistoricalFS!E33/SUM(HistoricalFS!E47:E48),0) -> -0.24236702 | F23: =IFERROR(HistoricalFS!F33/SUM(HistoricalFS!F47:F48),0) -> -0.25024214 | G23: =IFERROR(HistoricalFS!G33/SUM(HistoricalFS!G47:G48),0) -> -0.049254268 | H23: =IFERROR(HistoricalFS!H33/SUM(HistoricalFS!H47:H48),0) -> -0.015066127 | I23: =IFERROR(HistoricalFS!I33/SUM(HistoricalFS!I47:I48),0) -> -0.014699958 | J23: =IFERROR(HistoricalFS!J33/SUM(HistoricalFS!J47:J48),0) -> -0.060110263 | ... L23: =IFERROR(HistoricalFS!L33/SUM(HistoricalFS!L47:L48),0) -> 0.050279194 | N23: =IFERROR(AVERAGE(C23:L23),0) -> -0.086711533 | O23: =IFERROR(MEDIAN(C23:L23),0) -> -0.032160198
B24: Self Sustained Growth Rate | C24: =IFERROR(C22*C23,0) -> 0 | D24: =IFERROR(D22*D23,0) -> 0 | E24: =IFERROR(E22*E23,0) -> 0 | F24: =IFERROR(F22*F23,0) -> 0 | G24: =IFERROR(G22*G23,0) -> 0 | H24: =IFERROR(H22*H23,0) -> 0 | I24: =IFERROR(I22*I23,0) -> 0 | J24: =IFERROR(J22*J23,0) -> 0 | ... L24: =IFERROR(L22*L23,0) -> 0.027988874 | N24: =IFERROR(AVERAGE(C24:L24),0) -> 0.0034932097 | O24: =IFERROR(MEDIAN(C24:L24),0) -> 0
B25: Interest Coverage Ratio | C25: =IFERROR((HistoricalFS!C18-HistoricalFS!C24)/HistoricalFS!C21,0) -> 0.1410775 | D25: =IFERROR((HistoricalFS!D18-HistoricalFS!D24)/HistoricalFS!D21,0) -> 1.0453854 | E25: =IFERROR((HistoricalFS!E18-HistoricalFS!E24)/HistoricalFS!E21,0) -> -0.013648883 | F25: =IFERROR((HistoricalFS!F18-HistoricalFS!F24)/HistoricalFS!F21,0) -> 0.16229736 | G25: =IFERROR((HistoricalFS!G18-HistoricalFS!G24)/HistoricalFS!G21,0) -> 0.92829565 | H25: =IFERROR((HistoricalFS!H18-HistoricalFS!H24)/HistoricalFS!H21,0) -> 1.0412853 | I25: =IFERROR((HistoricalFS!I18-HistoricalFS!I24)/HistoricalFS!I21,0) -> 1.0128711 | J25: =IFERROR((HistoricalFS!J18-HistoricalFS!J24)/HistoricalFS!J21,0) -> 0.98099345 | ... L25: =IFERROR((HistoricalFS!L18-HistoricalFS!L24)/HistoricalFS!L21,0) -> 1.7116072 | N25: =IFERROR(AVERAGE(C25:L25),0) -> 0.85099655 | O25: =IFERROR(MEDIAN(C25:L25),0) -> 0.99693229
B27: Debtor Turnover Ratio | C27: =IFERROR(HistoricalFS!C6/HistoricalFS!C59,0) -> 8.3311583 | D27: =IFERROR(HistoricalFS!D6/HistoricalFS!D59,0) -> 7.1990413 | E27: =IFERROR(HistoricalFS!E6/HistoricalFS!E59,0) -> 9.6238593 | F27: =IFERROR(HistoricalFS!F6/HistoricalFS!F59,0) -> 6.722005 | G27: =IFERROR(HistoricalFS!G6/HistoricalFS!G59,0) -> 6.5831514 | H27: =IFERROR(HistoricalFS!H6/HistoricalFS!H59,0) -> 6.2890013 | I27: =IFERROR(HistoricalFS!I6/HistoricalFS!I59,0) -> 7.1601223 | J27: =IFERROR(HistoricalFS!J6/HistoricalFS!J59,0) -> 7.9269118 | ... L27: =IFERROR(HistoricalFS!L6/HistoricalFS!L59,0) -> 11.467734 | N27: =IFERROR(AVERAGE(C27:L27),0) -> 7.9604995 | O27: =IFERROR(MEDIAN(C27:L27),0) -> 7.5629765
B28: Creditor Turnover Ratio | C28: =HistoricalFS!C6/HistoricalFS!C50 -> 1.5067685 | D28: =HistoricalFS!D6/HistoricalFS!D50 -> 1.3263711 | E28: =HistoricalFS!E6/HistoricalFS!E50 -> 1.5879298 | F28: =HistoricalFS!F6/HistoricalFS!F50 -> 1.7310422 | G28: =HistoricalFS!G6/HistoricalFS!G50 -> 1.6033891 | H28: =HistoricalFS!H6/HistoricalFS!H50 -> 1.103923 | I28: =HistoricalFS!I6/HistoricalFS!I50 -> 1.1002834 | J28: =HistoricalFS!J6/HistoricalFS!J50 -> 1.1880616 | ... L28: =HistoricalFS!L6/HistoricalFS!L50 -> 1.1390129 | N28: =IFERROR(AVERAGE(C28:L28),0) -> 1.3445984 | O28: =IFERROR(MEDIAN(C28:L28),0) -> 1.2572163
B29: Inventory Turnover Ratio | C29: =HistoricalFS!C6/HistoricalFS!C60 -> 21.47539 | D29: =HistoricalFS!D6/HistoricalFS!D60 -> 17.246987 | E29: =HistoricalFS!E6/HistoricalFS!E60 -> 16.536628 | F29: =HistoricalFS!F6/HistoricalFS!F60 -> 17.510964 | G29: =HistoricalFS!G6/HistoricalFS!G60 -> 16.627027 | H29: =HistoricalFS!H6/HistoricalFS!H60 -> 17.343532 | I29: =HistoricalFS!I6/HistoricalFS!I60 -> 10.118272 | J29: =HistoricalFS!J6/HistoricalFS!J60 -> 13.97686 | ... L29: =HistoricalFS!L6/HistoricalFS!L60 -> 14.322139 | N29: =IFERROR(AVERAGE(C29:L29),0) -> 15.906143 | O29: =IFERROR(MEDIAN(C29:L29),0) -> 16.581827
B30: Fixed Asset Turnover Ratio | C30: =IFERROR(HistoricalFS!C6/HistoricalFS!C53,0) -> 0.80997767 | D30: =IFERROR(HistoricalFS!D6/HistoricalFS!D53,0) -> 0.59207456 | E30: =IFERROR(HistoricalFS!E6/HistoricalFS!E53,0) -> 0.6010416 | F30: =IFERROR(HistoricalFS!F6/HistoricalFS!F53,0) -> 0.67444158 | G30: =IFERROR(HistoricalFS!G6/HistoricalFS!G53,0) -> 0.61125645 | H30: =IFERROR(HistoricalFS!H6/HistoricalFS!H53,0) -> 0.62675053 | I30: =IFERROR(HistoricalFS!I6/HistoricalFS!I53,0) -> 0.74605485 | J30: =IFERROR(HistoricalFS!J6/HistoricalFS!J53,0) -> 0.89250301 | ... L30: =IFERROR(HistoricalFS!L6/HistoricalFS!L53,0) -> 0.83545411 | N30: =IFERROR(AVERAGE(C30:L30),0) -> 0.73038425 | O30: =IFERROR(MEDIAN(C30:L30),0) -> 0.71024821
B31: Capital Turnover Ratio | C31: =IFERROR(HistoricalFS!C6/SUM(HistoricalFS!C47,HistoricalFS!C48),0) -> 2.5353165 | D31: =IFERROR(HistoricalFS!D6/SUM(HistoricalFS!D47,HistoricalFS!D48),0) -> 2.0876678 | E31: =IFERROR(HistoricalFS!E6/SUM(HistoricalFS!E47,HistoricalFS!E48),0) -> 1.6366138 | F31: =IFERROR(HistoricalFS!F6/SUM(HistoricalFS!F47,HistoricalFS!F48),0) -> 1.6323533 | G31: =IFERROR(HistoricalFS!G6/SUM(HistoricalFS!G47,HistoricalFS!G48),0) -> 1.4891312 | H31: =IFERROR(HistoricalFS!H6/SUM(HistoricalFS!H47,HistoricalFS!H48),0) -> 1.4650537 | I31: =IFERROR(HistoricalFS!I6/SUM(HistoricalFS!I47,HistoricalFS!I48),0) -> 1.9078741 | J31: =IFERROR(HistoricalFS!J6/SUM(HistoricalFS!J47,HistoricalFS!J48),0) -> 1.9143453 | ... L31: =IFERROR(HistoricalFS!L6/SUM(HistoricalFS!L47,HistoricalFS!L48),0) -> 1.8269257 | N31: =IFERROR(AVERAGE(C31:L31),0) -> 1.8394473 | O31: =IFERROR(MEDIAN(C31:L31),0) -> 1.8630587
B34: Debtor Days | C34: =IFERROR((365/C27),0) -> 43.811435 | D34: =IFERROR((365/D27),0) -> 50.701196 | E34: =IFERROR((365/E27),0) -> 37.926573 | F34: =IFERROR((365/F27),0) -> 54.299275 | G34: =IFERROR((365/G27),0) -> 55.44457 | H34: =IFERROR((365/H27),0) -> 58.037832 | I34: =IFERROR((365/I27),0) -> 50.976783 | J34: =IFERROR((365/J27),0) -> 46.045674 | ... L34: =IFERROR((365/L27),0) -> 31.828432 | N34: =IFERROR(AVERAGE(C34:L34),0) -> 47.303703 | O34: =IFERROR(MEDIAN(C34:L34),0) -> 48.373435
B35: Payable Days | C35: =IFERROR(365/C28,0) -> 242.24027 | D35: =IFERROR(365/D28,0) -> 275.18694 | E35: =IFERROR(365/E28,0) -> 229.85902 | F35: =IFERROR(365/F28,0) -> 210.85563 | G35: =IFERROR(365/G28,0) -> 227.64281 | H35: =IFERROR(365/H28,0) -> 330.63901 | I35: =IFERROR(365/I28,0) -> 331.73271 | J35: =IFERROR(365/J28,0) -> 307.22313 | ... L35: =IFERROR(365/L28,0) -> 320.45292 | N35: =IFERROR(AVERAGE(C35:L35),0) -> 279.07042 | O35: =IFERROR(MEDIAN(C35:L35),0) -> 291.20504
B36: Inventory Days | C36: =IFERROR(365/C29,0) -> 16.996199 | D36: =IFERROR(365/D29,0) -> 21.163117 | E36: =IFERROR(365/E29,0) -> 22.072215 | F36: =IFERROR(365/F29,0) -> 20.844083 | G36: =IFERROR(365/G29,0) -> 21.952211 | H36: =IFERROR(365/H29,0) -> 21.04531 | I36: =IFERROR(365/I29,0) -> 36.073354 | J36: =IFERROR(365/J29,0) -> 26.114593 | ... L36: =IFERROR(365/L29,0) -> 25.485021 | N36: =IFERROR(AVERAGE(C36:L36),0) -> 23.799824 | O36: =IFERROR(MEDIAN(C36:L36),0) -> 22.012213
B37: Cash Conversion Cycle (in days) | C37: =SUM(C34,C36)-C35 -> -181.43263 | D37: =SUM(D34,D36)-D35 -> -203.32263 | E37: =SUM(E34,E36)-E35 -> -169.86023 | F37: =SUM(F34,F36)-F35 -> -135.71228 | G37: =SUM(G34,G36)-G35 -> -150.24603 | H37: =SUM(H34,H36)-H35 -> -251.55587 | I37: =SUM(I34,I36)-I35 -> -244.68257 | J37: =SUM(J34,J36)-J35 -> -235.06286 | ... L37: =SUM(L34,L36)-L35 -> -263.13946 | N37: =IFERROR(AVERAGE(C37:L37),0) -> -207.9669 | O37: =IFERROR(MEDIAN(C37:L37),0) -> -219.19275
B39: CFO/Sales | C39: =IFERROR(HistoricalFS!C70/HistoricalFS!C6,0) -> 1.2849785 | D39: =IFERROR(HistoricalFS!D70/HistoricalFS!D6,0) -> 1.0946679 | E39: =IFERROR(HistoricalFS!E70/HistoricalFS!E6,0) -> 0.88886662 | F39: =IFERROR(HistoricalFS!F70/HistoricalFS!F6,0) -> 0.63219812 | G39: =IFERROR(HistoricalFS!G70/HistoricalFS!G6,0) -> 0.91407886 | H39: =IFERROR(HistoricalFS!H70/HistoricalFS!H6,0) -> 0.88677599 | I39: =IFERROR(HistoricalFS!I70/HistoricalFS!I6,0) -> 0.33358885 | J39: =IFERROR(HistoricalFS!J70/HistoricalFS!J6,0) -> 0.64214482 | ... L39: =IFERROR(HistoricalFS!L70/HistoricalFS!L6,0) -> 0.96370947 | N39: =IFERROR(AVERAGE(C39:L39),0) -> 0.87462364 | O39: =IFERROR(MEDIAN(C39:L39),0) -> 0.90147274
B40: CFO/Total Assets | C40: =IFERROR(HistoricalFS!C70/HistoricalFS!C64,0) -> 0.54098527 | D40: =IFERROR(HistoricalFS!D70/HistoricalFS!D64,0) -> 0.3645964 | E40: =IFERROR(HistoricalFS!E70/HistoricalFS!E64,0) -> 0.29132856 | F40: =IFERROR(HistoricalFS!F70/HistoricalFS!F64,0) -> 0.22469343 | G40: =IFERROR(HistoricalFS!G70/HistoricalFS!G64,0) -> 0.29699764 | H40: =IFERROR(HistoricalFS!H70/HistoricalFS!H64,0) -> 0.29395932 | I40: =IFERROR(HistoricalFS!I70/HistoricalFS!I64,0) -> 0.1269021 | J40: =IFERROR(HistoricalFS!J70/HistoricalFS!J64,0) -> 0.27626133 | ... L40: =IFERROR(HistoricalFS!L70/HistoricalFS!L64,0) -> 0.4039994 | N40: =IFERROR(AVERAGE(C40:L40),0) -> 0.33081294 | O40: =IFERROR(MEDIAN(C40:L40),0) -> 0.29547848
B41: CFO/Total Debt | C41: =IFERROR(HistoricalFS!C70/HistoricalFS!C49,0) -> 0.97557054 | D41: =IFERROR(HistoricalFS!D70/HistoricalFS!D49,0) -> 0.61864174 | E41: =IFERROR(HistoricalFS!E70/HistoricalFS!E49,0) -> 0.49100212 | F41: =IFERROR(HistoricalFS!F70/HistoricalFS!F49,0) -> 0.3894515 | G41: =IFERROR(HistoricalFS!G70/HistoricalFS!G49,0) -> 0.51280158 | H41: =IFERROR(HistoricalFS!H70/HistoricalFS!H49,0) -> 0.62089023 | I41: =IFERROR(HistoricalFS!I70/HistoricalFS!I49,0) -> 0.27898811 | J41: =IFERROR(HistoricalFS!J70/HistoricalFS!J49,0) -> 0.66866977 | ... L41: =IFERROR(HistoricalFS!L70/HistoricalFS!L49,0) -> 1.0037572 | N41: =IFERROR(AVERAGE(C41:L41),0) -> 0.68247327 | O41: =IFERROR(MEDIAN(C41:L41),0) -> 0.61976599

Sheet Data >
B2: ='Data Sheet'!$B$1&" - "&'Data Sheet'!$A$17&" Forecasting" -> TATA POWER COMPANY LTD - Sales Forecasting | G2: ='Data Sheet'!$B$1&" - "&HistoricalFS!B18&" Forecasting" -> TATA POWER COMPANY LTD - EBIDTA Forecasting | L2: ='Data Sheet'!$B$1&" - "&HistoricalFS!B38&" Forecasting" -> TATA POWER COMPANY LTD - Earning per Share Forecasting
B3: Year Weight | C3: Year | D3: Sales | E3: Sales Growth | G3: Year Weight | H3: Year | I3: Sales | J3: Sales Growth | L3: Year Weight | M3: Year | N3: Sales | O3: Sales Growth
B4: 1 | C4: ='Data Sheet'!$B$16 -> 42460 | D4: 29494.3 | G4: 1 | H4: ='Data Sheet'!$B$16 -> 42460 | I4: {=TRANSPOSE(HistoricalFS!C18:L18)} -> 2105.23 | L4: 1 | M4: ='Data Sheet'!$B$16 -> 42460 | N4: {=TRANSPOSE(HistoricalFS!C38:L38)} -> -12.791614
B5: =B4+1 -> 2 | C5: =C4+365 -> 42825 | D5: 27587.59 | E5: =IFERROR(D5/D4-1,0) -> -0.064646728 | G5: =G4+1 -> 2 | H5: =H4+365 -> 42825 | I5: 5473.27 | J5: =IFERROR(I5/I4-1,0) -> 1.5998442 | L5: =L4+1 -> 2 | M5: =M4+365 -> 42825 | N5: -0.73107069 | O5: =IFERROR(N5/N4-1,0) -> -0.94284766
B6: =B5+1 -> 3 | C6: =C5+365 -> 43190 | D6: 26840.27 | E6: =IFERROR(D6/D5-1,0) -> -0.027088992 | G6: =G5+1 -> 3 | H6: =H5+365 -> 43190 | I6: 2294.83 | J6: =IFERROR(I6/I5-1,0) -> -0.58072048 | L6: =L5+1 -> 3 | M6: =M5+365 -> 43190 | N6: -14.695319 | O6: =IFERROR(N6/N5-1,0) -> 19.101092
B7: =B6+1 -> 4 | C7: =C6+365 -> 43555 | D7: 29881.06 | E7: =IFERROR(D7/D6-1,0) -> 0.11329208 | G7: =G6+1 -> 4 | H7: =H6+365 -> 43555 | I7: 3069.91 | J7: =IFERROR(I7/I6-1,0) -> 0.33775051 | L7: =L6+1 -> 4 | M7: =M6+365 -> 43555 | N7: -16.935855 | O7: =IFERROR(N7/N6-1,0) -> 0.15246592
B8: =B7+1 -> 5 | C8: =C7+365 -> 43920 | D8: 29136.37 | E8: =IFERROR(D8/D7-1,0) -> -0.024921807 | G8: =G7+1 -> 5 | H8: =H7+365 -> 43920 | I8: 6805.07 | J8: =IFERROR(I8/I7-1,0) -> 1.2167002 | L8: =L7+1 -> 5 | M8: =M7+365 -> 43920 | N8: -3.5629621 | O8: =IFERROR(N8/N7-1,0) -> -0.78962018
B9: =B8+1 -> 6 | C9: =C8+365 -> 44285 | D9: 32703.31 | E9: =IFERROR(D9/D8-1,0) -> 0.12242225 | G9: =G8+1 -> 6 | H9: =H8+365 -> 44285 | I9: 6920.9 | J9: =IFERROR(I9/I8-1,0) -> 0.017021133 | L9: =L8+1 -> 6 | M9: =M8+365 -> 44285 | N9: -1.0525146 | O9: =IFERROR(N9/N8-1,0) -> -0.70459562
B10: =B9+1 -> 7 | C10: =C9+365 -> 44650 | D10: 42815.67 | E10: =IFERROR(D10/D9-1,0) -> 0.30921518 | G10: =G9+1 -> 7 | H10: =H9+365 -> 44650 | I10: 7030.89 | J10: =IFERROR(I10/I9-1,0) -> 0.015892442 | L10: =L9+1 -> 7 | M10: =M9+365 -> 44650 | N10: -1.0324226 | O10: =IFERROR(N10/N9-1,0) -> -0.01908953
B11: =B10+1 -> 8 | C11: =C10+365 -> 45015 | D11: 55109.08 | E11: =IFERROR(D11/D10-1,0) -> 0.28712408 | G11: =G10+1 -> 8 | H11: =H10+365 -> 45015 | I11: 7727.76 | J11: =IFERROR(I11/I10-1,0) -> 0.099115475 | L11: =L10+1 -> 8 | M11: =M10+365 -> 45015 | N11: -5.4155165 | O11: =IFERROR(N11/N10-1,0) -> 4.2454455
B12: =B11+1 -> 9 | C12: =C11+365 -> 45380 | D12: 61448.9 | E12: =IFERROR(D12/D11-1,0) -> 0.1150413 | G12: =G11+1 -> 9 | H12: =H11+365 -> 45380 | I12: 10735.28 | J12: =IFERROR(I12/I11-1,0) -> 0.38918393 | L12: =L11+1 -> 9 | M12: =M11+365 -> 45380 | N12: 2.7032517 | O12: =IFERROR(N12/N11-1,0) -> -1.4991678
B13: =B12+1 -> 10 | C13: =C12+365 -> 45745 | D13: 65478.24 | E13: =IFERROR(D13/D12-1,0) -> 0.065572207 | G13: =G12+1 -> 10 | H13: =H12+365 -> 45745 | I13: 12165.59 | J13: =IFERROR(I13/I12-1,0) -> 0.13323453 | L13: =L12+1 -> 10 | M13: =M12+365 -> 45745 | N13: 5.6396582 | O13: =IFERROR(N13/N12-1,0) -> 1.0862498
B14: =B13+1 -> 11 | C14: =C13+365 -> 46110 | D14: =IFERROR(FORECAST(B14,$D$4:$D$13,$B$4:$B$13),0) -> 64869.461 | E14: =IFERROR(D14/D13-1,0) -> -0.0092974297 | G14: =G13+1 -> 11 | H14: =H13+365 -> 46110 | I14: =FORECAST(G14,$I$4:$I$13,$G$4:$G$13) -> 11984.231 | J14: =IFERROR(I14/I13-1,0) -> -0.014907566 | L14: =L13+1 -> 11 | M14: =M13+365 -> 46110 | N14: =FORECAST(L14,N4:N13,L4:L13) -> 4.7639457 | O14: =IFERROR(N14/N13-1,0) -> -0.15527759
B15: =B14+1 -> 12 | C15: =C14+365 -> 46475 | D15: =IFERROR(FORECAST(B15,$D$4:$D$13,$B$4:$B$13),0) -> 69382.185 | E15: =IFERROR(D15/D14-1,0) -> 0.069566232 | G15: =G14+1 -> 12 | H15: =H14+365 -> 46475 | I15: =FORECAST(G15,$I$4:$I$13,$G$4:$G$13) -> 12993.568 | J15: =IFERROR(I15/I14-1,0) -> 0.084222157 | L15: =L14+1 -> 12 | M15: =M14+365 -> 46475 | N15: =FORECAST(L15,N5:N14,L5:L14) -> 6.4500512 | O15: =IFERROR(N15/N14-1,0) -> 0.35393046
B16: =B15+1 -> 13 | C16: =C15+365 -> 46840 | D16: =IFERROR(FORECAST(B16,$D$4:$D$13,$B$4:$B$13),0) -> 73894.909 | E16: =IFERROR(D16/D15-1,0) -> 0.065041537 | G16: =G15+1 -> 13 | H16: =H15+365 -> 46840 | I16: =FORECAST(G16,$I$4:$I$13,$G$4:$G$13) -> 14002.906 | J16: =IFERROR(I16/I15-1,0) -> 0.077679797 | L16: =L15+1 -> 13 | M16: =M15+365 -> 46840 | N16: =FORECAST(L16,N6:N15,L6:L15) -> 10.856373 | O16: =IFERROR(N16/N15-1,0) -> 0.68314527
B17: =B16+1 -> 14 | C17: =C16+365 -> 47205 | D17: =IFERROR(FORECAST(B17,$D$4:$D$13,$B$4:$B$13),0) -> 78407.632 | E17: =IFERROR(D17/D16-1,0) -> 0.061069484 | G17: =G16+1 -> 14 | H17: =H16+365 -> 47205 | I17: =FORECAST(G17,$I$4:$I$13,$G$4:$G$13) -> 15012.244 | J17: =IFERROR(I17/I16-1,0) -> 0.072080591 | L17: =L16+1 -> 14 | M17: =M16+365 -> 47205 | N17: =FORECAST(L17,N7:N16,L7:L16) -> 12.822683 | O17: =IFERROR(N17/N16-1,0) -> 0.18112031
B18: =B17+1 -> 15 | C18: =C17+365 -> 47570 | D18: =IFERROR(FORECAST(B18,$D$4:$D$13,$B$4:$B$13),0) -> 82920.356 | E18: =IFERROR(D18/D17-1,0) -> 0.057554651 | G18: =G17+1 -> 15 | H18: =H17+365 -> 47570 | I18: =FORECAST(G18,$I$4:$I$13,$G$4:$G$13) -> 16021.582 | J18: =IFERROR(I18/I17-1,0) -> 0.067234303 | L18: =L17+1 -> 15 | M18: =M17+365 -> 47570 | N18: =FORECAST(L18,N8:N17,L8:L17) -> 13.274594 | O18: =IFERROR(N18/N17-1,0) -> 0.035243112
B20: Average growth | D20: =AVERAGE(E5:E13) -> 0.099556619
B21: Geometric growth | D21: =((D13/D4)^(1/B13)-1) -> 0.083018538

Sheet Data Sheet
A1: COMPANY NAME | B1: TATA POWER COMPANY LTD | E1: =IF(B2<>B3, "A NEW VERSION OF THE WORKSHEET IS AVAILABLE", "")
A2: LATEST VERSION | B2: 2.1 | E2: PLEASE DO NOT MAKE ANY CHANGES TO THIS SHEET
A3: CURRENT VERSION | B3: 2.1
A5: META
A6: Number of shares | B6: =IF(B9>0, B9/B8, 0) -> 319.57733
A7: Face Value | B7: 1
A8: Current Price | B8: 367.4
A9: Market Capitalization | B9: 117412.71
A15: PROFIT & LOSS
A16: Report Date | B16: 42460 | C16: 42825 | D16: 43190 | E16: 43555 | F16: 43921 | G16: 44286 | H16: 44651 | I16: 45016 | J16: 45382 | K16: 45747
A17: Sales | B17: 29494.3 | C17: 27587.59 | D17: 26840.27 | E17: 29881.06 | F17: 29136.37 | G17: 32703.31 | H17: 42815.67 | I17: 55109.08 | J17: 61448.9 | K17: 65478.24
A18: Raw Material Cost
A19: Change in Inventory | B19: -34.16 | C19: -28.34 | D19: 8.51 | E19: -24.37 | F19: 15.64 | G19: -0.41 | H19: 199.22 | I19: -43.53 | J19: 51.78 | K19: 440.76
A20: Power and Fuel | B20: 17088.59 | C20: 17921.05 | D20: 16356.15 | E20: 18918.9 | F20: 17100.03 | G20: 20037.56 | H20: 26764.37 | I20: 36708.56 | J20: 39584.79 | K20: 39363.54
A21: Other Mfr. Exp | B21: 3146.34 | C21: 1720.75 | D21: 2041.68 | E21: 2056.1 | F21: 2013.68 | G21: 2533.43 | H21: 3942.93 | I21: 5007.21 | J21: 5272.77 | K21: 6306.19
A22: Employee Cost | B22: 1375.45 | C22: 1342.92 | D22: 1475 | E22: 1497.6 | F22: 1541.05 | G22: 2414.24 | H22: 3731.29 | I22: 3801.4 | J22: 4264.99 | K22: 4649.25
A23: Selling and admin | B23: 570.39 | C23: 481.89 | D23: 511.78 | E23: 466.39 | F23: 401.51 | G23: 523.94 | H23: 730.58 | I23: 1016.41 | J23: 1017.98 | K23: 1055.18
A24: Other Expenses | B24: 5174.14 | C24: 619.37 | D24: 4169.34 | E24: 3847.79 | F24: 1290.67 | G24: 272.83 | H24: 814.83 | I24: 804.21 | J24: 624.87 | K24: 2379.25
A25: Other Income | B25: 4060.02 | C25: 1297.37 | D25: 6585.64 | E25: 7186.47 | F25: 2280.15 | G25: 1774.96 | H25: 2485.5 | I25: 5540.09 | J25: 3416.33 | K25: 2973.33
A26: Depreciation | B26: 1648.73 | C26: 1955.59 | D26: 2346.17 | E26: 2393.13 | F26: 2633.56 | G26: 2744.94 | H26: 3122.2 | I26: 3439.2 | J26: 3786.37 | K26: 4116.86
A27: Interest | B27: 3235.81 | C27: 3364.96 | D27: 3761.48 | E27: 4170 | F27: 4493.73 | G27: 4010.39 | H27: 3859.02 | I27: 4371.65 | J27: 4633.22 | K27: 4702.44
A28: Profit before tax | B28: 1280.71 | C28: 1450.09 | D28: 2772.82 | E28: 3693.25 | F28: 1957.93 | G28: 1940.53 | H28: 2535.17 | I28: 5457 | J28: 5732.02 | K28: 6319.62
A29: Tax | B29: 680.31 | C29: 350.46 | D29: 161.97 | E29: 1087.59 | F29: 641.49 | G29: 501.88 | H29: 379.56 | I29: 1647.33 | J29: 1451.92 | K29: 1544.25
A30: Net profit | B30: 662.2 | C30: 896.55 | D30: 2408.3 | E30: 2356.19 | F30: 1017.38 | G30: 1127.38 | H30: 1741.46 | I30: 3336.44 | J30: 3696.25 | K30: 3971
A31: Dividend Amount | B31: 351.62 | C31: 351.65 | D31: 351.65 | E31: 351.65 | F31: 419.28 | G31: 495.32 | H31: 559.23 | I31: 639.12 | J31: 639.12 | K31: 798.9
A40: Quarters
A41: Report Date | B41: 45107 | C41: 45199 | D41: 45291 | E41: 45382 | F41: 45473 | G41: 45565 | H41: 45657 | I41: 45747 | J41: 45838 | K41: 45930
A42: Sales | B42: 15213.29 | C42: 15738.03 | D42: 14651 | E42: 15846.58 | F42: 17293.62 | G42: 15697.67 | H42: 15391.06 | I42: 17095.88 | J42: 18035.07 | K42: 15544.91
A43: Expenses | B43: 12499.94 | C43: 12966.92 | D43: 12233.58 | E43: 13539.69 | F43: 14231.87 | G43: 12426.76 | H43: 12312.03 | I43: 14027.62 | J43: 14469.9 | K43: 12242.96
A44: Other Income | B44: 877.05 | C44: 567.29 | D44: 1091.87 | E44: 1406.63 | F44: 577.72 | G44: 631.75 | H44: 588.55 | I44: 860.92 | J44: 494.42 | K44: 858.65
A45: Depreciation | B45: 893.44 | C45: 925.89 | D45: 926.27 | E45: 1040.77 | F45: 972.89 | G45: 986.69 | H45: 1040.99 | I45: 1116.28 | J45: 1160.91 | K45: 1162.05
A46: Interest | B46: 1221.41 | C46: 1181.83 | D46: 1094.26 | E46: 1135.72 | F46: 1176.24 | G46: 1143.1 | H46: 1169.9 | I46: 1213.21 | J46: 1279.22 | K46: 1318.65
A47: Profit before tax | B47: 1475.55 | C47: 1230.68 | D47: 1488.76 | E47: 1537.03 | F47: 1490.34 | G47: 1772.87 | H47: 1456.69 | I47: 1599.69 | J47: 1619.46 | K47: 1679.9
A48: Tax | B48: 334.58 | C48: 213.27 | D48: 412.64 | E48: 491.44 | F48: 301.71 | G48: 679.79 | H48: 269.15 | I48: 293.6 | J48: 357.14 | K48: 434.51
A49: Net profit | B49: 972.49 | C49: 875.53 | D49: 953.01 | E49: 895.21 | F49: 970.91 | G49: 926.53 | H49: 1030.7 | I49: 1042.83 | J49: 1059.86 | K49: 919.44
A50: Operating Profit | B50: 2713.35 | C50: 2771.11 | D50: 2417.42 | E50: 2306.89 | F50: 3061.75 | G50: 3270.91 | H50: 3079.03 | I50: 3068.26 | J50: 3565.17 | K50: 3301.95
A55: BALANCE SHEET
A56: Report Date | B56: 42460 | C56: 42825 | D56: 43190 | E56: 43555 | F56: 43921 | G56: 44286 | H56: 44651 | I56: 45016 | J56: 45382 | K56: 45747
A57: Equity Share Capital | B57: 270.48 | C57: 270.5 | D57: 270.5 | E57: 270.5 | F57: 270.5 | G57: 319.56 | H57: 319.56 | I57: 319.56 | J57: 319.56 | K57: 319.56
A58: Reserves | B58: 11362.9 | C58: 12944.05 | D58: 16129.38 | E58: 18035.01 | F58: 19295.52 | G58: 22002.7 | H58: 22122 | I58: 28467.87 | J58: 32035.73 | K58: 35521.11
...

Sheet Cash Flow Data
C2: 41699 | D2: 42064 | E2: 42430 | F2: 42795 | G2: 43160 | H2: 43525 | I2: 43891 | J2: 44256 | K2: 44621 | L2: 44986 | M2: 45352 | N2: 45717
B3: Cash from Operating Activity - | C3: 36151 | D3: 35531 | E3: 37900 | F3: 30199 | G3: 23857 | H3: 18891 | I3: 26633 | J3: 29001 | K3: 14283 | L3: 35388 | M3: 67915 | N3: 63102
B4: Profit from operations | C4: 36303 | D4: 43397 | E4: 38626 | F4: 28840 | G4: 33312 | H4: 28771 | I4: 23352 | J4: 31198 | K4: 26943 | L4: 41694 | M4: 65106 | N4: 58937
B5: Receivables | C5: 445 | D5: -3179 | E5: -2223 | F5: -4152 | G5: -10688 | H5: -9109 | I5: 9950 | J5: -5505 | K5: 185 | L5: -2213 | M5: -1876 | N5: 3573
B6: Inventory | C6: -2853 | D6: -3692 | E6: -5743 | F6: -6621 | G6: -3560 | H6: 2069 | I6: 2326 | J6: 3814 | K6: 472 | L6: -5665 | M6: -7265 | N6: 2127
B7: Payables | C7: 4694 | D7: 3598 | E7: 3947 | F7: 9301 | G7: 7320 | H7: -4692 | I7: -8085 | J7: 5748 | K7: -7012 | L7: 6945 | M7: 13706 | N7: 1303
B8: Loans Advances | C8: 0 | D8: 0 | E8: -520 | F8: 0 | G8: 0 | H8: 0 | I8: 0 | J8: 0 | K8: 0 | L8: 0 | M8: 0 | N8: 0
B9: Other WC items | C9: 1870 | D9: -398 | E9: 5852 | F9: 4727 | G9: 494 | H9: 4512 | I9: 875 | J9: -4150 | K9: -4396 | L9: -2194 | M9: 2760 | N9: 1153
B10: Working capital changes | C10: 4157 | D10: -3672 | E10: 1313 | F10: 3254 | G10: -6434 | H10: -7221 | I10: 5065 | J10: -93 | K10: -10750 | L10: -3127 | M10: 7325 | N10: 8156
B11: Direct taxes | C11: -4308 | D11: -4194 | E11: -2040 | F11: -1895 | G11: -3021 | H11: -2659 | I11: -1785 | J11: -2105 | K11: -1910 | L11: -3179 | M11: -4516 | N11: -3991
B12: Cash from Investing Activity - | C12: -27991 | D12: -36232 | E12: -36694 | F12: -39571 | G12: -25139 | H12: -20878 | I12: -33115 | J12: -25672 | K12: -4444 | L12: -15417 | M12: -22781 | N12: -49982
B13: Fixed assets purchased | C13: -26975 | D13: -31962 | E13: -31503 | F13: -16072 | G13: -35079 | H13: -35304 | I13: -29702 | J13: -20205 | K13: -15168 | L13: -19230 | M13: -31414 | N13: -38042
B14: Fixed assets sold | C14: 50 | D14: 74 | E14: 59 | F14: 53 | G14: 30 | H14: 67 | I14: 171 | J14: 351 | K14: 230 | L14: 285 | M14: 231 | N14: 974
... B33: Net Cash Flow | C33: 4277 | D33: 4500 | E33: -2589 | F33: -3167 | G33: 730 | H33: 6843 | I33: -3092 | J33: 13232 | K33: 6459 | L33: -6272 | M33: 8128 | N33: -5666
